<?xml version="1.0" ?>
<mujoco model="Animat">
	<compiler autolimits="true" boundmass="1e-06" boundinertia="1e-12" angle="radian" eulerseq="XYZ" convexhull="true" fusestatic="true"/>
	<option timestep="0.0001" gravity="0 0 -9810" integrator="Euler" solver="Newton" iterations="1000" tolerance="1e-12" noslip_iterations="100" noslip_tolerance="1e-08" mpr_iterations="100">
		<flag multiccd="enable" energy="enable"/>
		<!--multiccd seems to fix leg penetrating the floor-->
	</option>
	<size njmax="4096" nconmax="4096"/>
	<visual>
		<global offwidth="1280" offheight="720"/>
		<quality shadowsize="1024" offsamples="4" numslices="28" numstacks="16" numquads="4"/>
		<map stiffness="100.0" stiffnessrot="500.0" force="2.0" torque="1.0" alpha="0.3" fogstart="3.0" fogend="10.0" znear="0.0001" zfar="3.0" haze="0.3" shadowclip="1.0" shadowscale="0.3" actuatortendon="2.0"/>
		<scale forcewidth="12.0" contactwidth="12.0" contactheight="50.0" connect="1.0" com="1.0" camera="1.0" light="1.0" selectpoint="1.0" jointlength="1.0" jointwidth="1.0" actuatorlength="1.0" actuatorwidth="1.0" framelength="0.01" framewidth="0.01" constraint="0.01" slidercrank="0.01"/>
	</visual>
	<statistic meanmass="1.0" meaninertia="1.0" meansize="1.0"/>
	<default>
		<default class="nmf"/>
	</default>
	<asset>
		<mesh name="mesh_Thorax" class="nmf" file="../mesh/Thorax.stl" scale="1000 1000 1000"/>
		<mesh name="mesh_A1A2" class="nmf" file="../mesh/A1A2.stl" scale="1000 1000 1000"/>
		<mesh name="mesh_A3" class="nmf" file="../mesh/A3.stl" scale="1000 1000 1000"/>
		<mesh name="mesh_A4" class="nmf" file="../mesh/A4.stl" scale="1000 1000 1000"/>
		<mesh name="mesh_A5" class="nmf" file="../mesh/A5.stl" scale="1000 1000 1000"/>
		<mesh name="mesh_A6" class="nmf" file="../mesh/A6.stl" scale="1000 1000 1000"/>
		<mesh name="mesh_Head" class="nmf" file="../mesh/Head.stl" scale="1000 1000 1000"/>
		<mesh name="mesh_LEye" class="nmf" file="../mesh/LEye.stl" scale="1000 1000 1000"/>
		<mesh name="mesh_LPedicel" class="nmf" file="../mesh/LPedicel.stl" scale="1000 1000 1000"/>
		<mesh name="mesh_LFuniculus" class="nmf" file="../mesh/LFuniculus.stl" scale="1000 1000 1000"/>
		<mesh name="mesh_LArista" class="nmf" file="../mesh/LArista.stl" scale="1000 1000 1000"/>
		<mesh name="mesh_REye" class="nmf" file="../mesh/REye.stl" scale="1000 1000 1000"/>
		<mesh name="mesh_Rostrum" class="nmf" file="../mesh/Rostrum.stl" scale="1000 1000 1000"/>
		<mesh name="mesh_Haustellum" class="nmf" file="../mesh/Haustellum.stl" scale="1000 1000 1000"/>
		<mesh name="mesh_RPedicel" class="nmf" file="../mesh/RPedicel.stl" scale="1000 1000 1000"/>
		<mesh name="mesh_RFuniculus" class="nmf" file="../mesh/RFuniculus.stl" scale="1000 1000 1000"/>
		<mesh name="mesh_RArista" class="nmf" file="../mesh/RArista.stl" scale="1000 1000 1000"/>
		<mesh name="mesh_LFCoxa" class="nmf" file="../mesh/LFCoxa.stl" scale="1000 1000 1000"/>
		<mesh name="mesh_LFFemur" class="nmf" file="../mesh/LFFemur.stl" scale="1000 1000 1000"/>
		<mesh name="mesh_LFTibia" class="nmf" file="../mesh/LFTibia.stl" scale="1000 1000 1000"/>
		<mesh name="mesh_LFTarsus1" class="nmf" file="../mesh/LFTarsus1.stl" scale="1000 1000 1000"/>
		<mesh name="mesh_LFTarsus2" class="nmf" file="../mesh/LFTarsus2.stl" scale="1000 1000 1000"/>
		<mesh name="mesh_LFTarsus3" class="nmf" file="../mesh/LFTarsus3.stl" scale="1000 1000 1000"/>
		<mesh name="mesh_LFTarsus4" class="nmf" file="../mesh/LFTarsus4.stl" scale="1000 1000 1000"/>
		<mesh name="mesh_LFTarsus5" class="nmf" file="../mesh/LFTarsus5.stl" scale="1000 1000 1000"/>
		<mesh name="mesh_LHaltere" class="nmf" file="../mesh/LHaltere.stl" scale="1000 1000 1000"/>
		<mesh name="mesh_LHCoxa" class="nmf" file="../mesh/LHCoxa.stl" scale="1000 1000 1000"/>
		<mesh name="mesh_LHFemur" class="nmf" file="../mesh/LHFemur.stl" scale="1000 1000 1000"/>
		<mesh name="mesh_LHTibia" class="nmf" file="../mesh/LHTibia.stl" scale="1000 1000 1000"/>
		<mesh name="mesh_LHTarsus1" class="nmf" file="../mesh/LHTarsus1.stl" scale="1000 1000 1000"/>
		<mesh name="mesh_LHTarsus2" class="nmf" file="../mesh/LHTarsus2.stl" scale="1000 1000 1000"/>
		<mesh name="mesh_LHTarsus3" class="nmf" file="../mesh/LHTarsus3.stl" scale="1000 1000 1000"/>
		<mesh name="mesh_LHTarsus4" class="nmf" file="../mesh/LHTarsus4.stl" scale="1000 1000 1000"/>
		<mesh name="mesh_LHTarsus5" class="nmf" file="../mesh/LHTarsus5.stl" scale="1000 1000 1000"/>
		<mesh name="mesh_LMCoxa" class="nmf" file="../mesh/LMCoxa.stl" scale="1000 1000 1000"/>
		<mesh name="mesh_LMFemur" class="nmf" file="../mesh/LMFemur.stl" scale="1000 1000 1000"/>
		<mesh name="mesh_LMTibia" class="nmf" file="../mesh/LMTibia.stl" scale="1000 1000 1000"/>
		<mesh name="mesh_LMTarsus1" class="nmf" file="../mesh/LMTarsus1.stl" scale="1000 1000 1000"/>
		<mesh name="mesh_LMTarsus2" class="nmf" file="../mesh/LMTarsus2.stl" scale="1000 1000 1000"/>
		<mesh name="mesh_LMTarsus3" class="nmf" file="../mesh/LMTarsus3.stl" scale="1000 1000 1000"/>
		<mesh name="mesh_LMTarsus4" class="nmf" file="../mesh/LMTarsus4.stl" scale="1000 1000 1000"/>
		<mesh name="mesh_LMTarsus5" class="nmf" file="../mesh/LMTarsus5.stl" scale="1000 1000 1000"/>
		<mesh name="mesh_LWing" class="nmf" file="../mesh/LWing.stl" scale="1000 1000 1000"/>
		<mesh name="mesh_RFCoxa" class="nmf" file="../mesh/RFCoxa.stl" scale="1000 1000 1000"/>
		<mesh name="mesh_RFFemur" class="nmf" file="../mesh/RFFemur.stl" scale="1000 1000 1000"/>
		<mesh name="mesh_RFTibia" class="nmf" file="../mesh/RFTibia.stl" scale="1000 1000 1000"/>
		<mesh name="mesh_RFTarsus1" class="nmf" file="../mesh/RFTarsus1.stl" scale="1000 1000 1000"/>
		<mesh name="mesh_RFTarsus2" class="nmf" file="../mesh/RFTarsus2.stl" scale="1000 1000 1000"/>
		<mesh name="mesh_RFTarsus3" class="nmf" file="../mesh/RFTarsus3.stl" scale="1000 1000 1000"/>
		<mesh name="mesh_RFTarsus4" class="nmf" file="../mesh/RFTarsus4.stl" scale="1000 1000 1000"/>
		<mesh name="mesh_RFTarsus5" class="nmf" file="../mesh/RFTarsus5.stl" scale="1000 1000 1000"/>
		<mesh name="mesh_RHaltere" class="nmf" file="../mesh/RHaltere.stl" scale="1000 1000 1000"/>
		<mesh name="mesh_RHCoxa" class="nmf" file="../mesh/RHCoxa.stl" scale="1000 1000 1000"/>
		<mesh name="mesh_RHFemur" class="nmf" file="../mesh/RHFemur.stl" scale="1000 1000 1000"/>
		<mesh name="mesh_RHTibia" class="nmf" file="../mesh/RHTibia.stl" scale="1000 1000 1000"/>
		<mesh name="mesh_RHTarsus1" class="nmf" file="../mesh/RHTarsus1.stl" scale="1000 1000 1000"/>
		<mesh name="mesh_RHTarsus2" class="nmf" file="../mesh/RHTarsus2.stl" scale="1000 1000 1000"/>
		<mesh name="mesh_RHTarsus3" class="nmf" file="../mesh/RHTarsus3.stl" scale="1000 1000 1000"/>
		<mesh name="mesh_RHTarsus4" class="nmf" file="../mesh/RHTarsus4.stl" scale="1000 1000 1000"/>
		<mesh name="mesh_RHTarsus5" class="nmf" file="../mesh/RHTarsus5.stl" scale="1000 1000 1000"/>
		<mesh name="mesh_RMCoxa" class="nmf" file="../mesh/RMCoxa.stl" scale="1000 1000 1000"/>
		<mesh name="mesh_RMFemur" class="nmf" file="../mesh/RMFemur.stl" scale="1000 1000 1000"/>
		<mesh name="mesh_RMTibia" class="nmf" file="../mesh/RMTibia.stl" scale="1000 1000 1000"/>
		<mesh name="mesh_RMTarsus1" class="nmf" file="../mesh/RMTarsus1.stl" scale="1000 1000 1000"/>
		<mesh name="mesh_RMTarsus2" class="nmf" file="../mesh/RMTarsus2.stl" scale="1000 1000 1000"/>
		<mesh name="mesh_RMTarsus3" class="nmf" file="../mesh/RMTarsus3.stl" scale="1000 1000 1000"/>
		<mesh name="mesh_RMTarsus4" class="nmf" file="../mesh/RMTarsus4.stl" scale="1000 1000 1000"/>
		<mesh name="mesh_RMTarsus5" class="nmf" file="../mesh/RMTarsus5.stl" scale="1000 1000 1000"/>
		<mesh name="mesh_RWing" class="nmf" file="../mesh/RWing.stl" scale="1000 1000 1000"/>
		<texture name="skybox" type="skybox" builtin="gradient" rgb1="1.0 1.0 1.0" rgb2="1.0 1.0 1.0" width="10" height="10"/>
	</asset>
	<worldbody>
		<body name="Thorax" pos="0.49564525485038757 -0.018091375008225441 1.2966440916061401" quat="1 0 0 0">
			<geom name="Thorax" class="nmf" type="mesh" contype="0" conaffinity="0" group="1" pos="0 0 0" quat="1 0 0 0" mesh="mesh_Thorax"/>
			<inertial pos="-0.46684262156486511 0.0074175349436700344 -0.015944290906190872" mass="0.3071677023684708" fullinertia="0.027243062516062268 0.033360193196103345 0.02751107597850627 -5.568571558756691e-07 -0.0027580533932364633 6.292056572389763e-07"/>
			<body name="A1A2" pos="-0.86162799596786499 -3.7252902984619141e-08 -0.16167950630187988" quat="1 0 0 0">
				<geom name="A1A2" class="nmf" type="mesh" contype="0" conaffinity="0" group="1" pos="0 0 0" quat="1 0 0 0" mesh="mesh_A1A2"/>
				<inertial pos="-0.23051536083221436 0.008398064412176609 0.064012818038463593" mass="0.085714247167182" fullinertia="0.005379033608322177 0.002884027603542622 0.004283720705434627 2.617637226361544e-07 0.0004016590408981329 -1.2583927987046114e-06"/>
				<body name="A3" pos="-0.35647359490394592 -1.3038516044616699e-08 -0.00070667266845703125" quat="0.9914448608983536 0 -0.13052619583150435 0">
					<geom name="A3" class="nmf" type="mesh" contype="0" conaffinity="0" condim="3" group="2" friction="1 0 0" solref="-1000000 -10000" margin="0.0" pos="0 0 0" quat="1 0 0 0" mesh="mesh_A3" fluidcoef="0 0 0 0 0"/>
					<inertial pos="-0.075963973999023438 0.0083986930549144745 -0.029380751773715019" mass="0.10703994712944608" fullinertia="0.008996439294317196 0.004180774634803926 0.006520358374758184 1.0357107862621634e-07 0.00021820474587532843 -3.950423364756016e-07"/>
					<body name="A4" pos="-0.23758499012713935 3.7252902984619141e-09 0.00035867633265751486" quat="0.9914448608983536 0 -0.13052619583150435 0">
						<geom name="A4" class="nmf" type="mesh" contype="0" conaffinity="0" condim="3" group="2" friction="1 0 0" solref="-1000000 -10000" margin="0.0" pos="0 0 0" quat="1 0 0 0" mesh="mesh_A4" fluidcoef="0 0 0 0 0"/>
						<inertial pos="-0.083291247487068176 0.0084340507164597511 -0.023897839710116386" mass="0.09752451180314971" fullinertia="0.008051631029536196 0.003257532197497144 0.0062418992743168466 2.3686085017703947e-07 0.00016058867127502458 -7.878101348949662e-08"/>
						<body name="A5" pos="-0.21429611215191624 0 -9.4213450204883031e-05" quat="0.99144486867831938 0 -0.13052613673678537 0">
							<geom name="A5" class="nmf" type="mesh" contype="0" conaffinity="0" condim="3" group="2" friction="1 0 0" solref="-1000000 -10000" margin="0.0" pos="0 0 0" quat="1 0 0 0" mesh="mesh_A5" fluidcoef="0 0 0 0 0"/>
							<inertial pos="-0.099572323262691498 0.0084852380678057671 -0.047328092157840729" mass="0.0970450221196675" fullinertia="0.006510034661406909 0.003395080422121763 0.00505859656001501 6.404385937523928e-07 -2.5107957418748027e-05 1.1672131908850304e-06"/>
							<body name="A6" pos="-0.2680491096907428 3.7252902984619141e-09 0.00050367089100911144" quat="0.9914448608983536 0 -0.13052619583150435 0">
								<geom name="A6" class="nmf" type="mesh" contype="0" conaffinity="0" condim="3" group="2" friction="1 0 0" solref="-1000000 -10000" margin="0.0" pos="0 0 0" quat="1 0 0 0" mesh="mesh_A6" fluidcoef="0 0 0 0 0"/>
								<inertial pos="-0.069944337010383606 0.0084731420502066612 -0.041498661041259766" mass="0.06267627178055471" fullinertia="0.0025686975223567004 0.0019706219398369054 0.002039626686007835 -7.322288496234474e-08 4.975882752051533e-05 -4.6929311054145495e-08"/>
							</body>
						</body>
					</body>
				</body>
			</body>
			<body name="Head_roll" pos="0.028699308633804321 -6.891787052154541e-08 0.00069832801818847656" quat="1 0 0 0">
				<joint name="joint_Head_roll" class="nmf" type="hinge" pos="0 0 0" axis="0 0 1" stiffness="0.0" springref="0.0" damping="0.2" frictionloss="0.0"/>
				<inertial pos="0 0 -9.5367433061710472e-08" mass="0.0" fullinertia="1e-09 1e-09 1e-09 0.0 0.0 0.0"/>
				<body name="Head_yaw" pos="0 0 -2.384185791015625e-07" quat="1 0 0 0">
					<joint name="joint_Head_yaw" class="nmf" type="hinge" pos="0 0 0" axis="1 0 0" stiffness="0.0" springref="0.0" damping="0.2" frictionloss="0.0"/>
					<inertial pos="0 0 -9.5367433061710472e-08" mass="0.0" fullinertia="1e-09 1e-09 1e-09 0.0 0.0 0.0"/>
					<body name="Head" pos="0 0 -2.384185791015625e-07" quat="1 0 0 0">
						<joint name="joint_Head" class="nmf" type="hinge" pos="0 0 0" axis="0 1 0" stiffness="0.0" springref="0.0" damping="0.2" frictionloss="0.0"/>
						<geom name="Head" class="nmf" type="mesh" contype="0" conaffinity="0" condim="3" group="2" friction="0 0 0" solref="-1000000 -10000" margin="0.0" pos="0 0 0" quat="1 0 0 0" mesh="mesh_Head"/>
						<inertial pos="0.21309308707714081 0.0028280734550207853 -0.02510833740234375" mass="0.09455094693981879" fullinertia="0.004544697353997133 0.0034240366967151553 0.0035964090705991017 -6.79724788760145e-05 0.00020875264623595435 1.895788565946054e-05"/>
						<body name="LEye" pos="0.23149168491363525 -0.00056653283536434174 0.017043113708496094" quat="1 0 0 0">
							<geom name="LEye" class="nmf" type="mesh" contype="0" conaffinity="0" condim="3" group="2" friction="0 0 0" solref="-1000000 -10000" margin="0.0" pos="0 0 0" quat="1 0 0 0" mesh="mesh_LEye"/>
							<inertial pos="0.0040917396545410156 0.30870887637138367 -0.019533826038241386" mass="0.012513500887563611" fullinertia="0.00017159827561930108 0.00023428433924930285 0.00011733661391825418 3.201087863081478e-05 1.3587085923434668e-05 -6.196620835615135e-06"/>
						</body>
						<body name="LPedicel_roll" pos="0.42920660972595215 0.090969029814004898 0.082306623458862305" quat="1 0 0 0">
							<joint name="joint_LPedicel_roll" class="nmf" type="hinge" pos="0 0 0" axis="0 0 1" stiffness="0.0" springref="0.0" damping="0.0001" frictionloss="0.0"/>
							<inertial pos="0 0 0" mass="0.0" fullinertia="1e-09 1e-09 1e-09 0.0 0.0 0.0"/>
							<body name="LPedicel_yaw" pos="-1.1920928955078125e-07 0 0" quat="1 0 0 0">
								<joint name="joint_LPedicel_yaw" class="nmf" type="hinge" pos="0 0 0" axis="1 0 0" stiffness="0.0" springref="0.0" damping="0.0001" frictionloss="0.0"/>
								<inertial pos="0 0 0" mass="0.0" fullinertia="1e-09 1e-09 1e-09 0.0 0.0 0.0"/>
								<body name="LPedicel" pos="-1.1920928955078125e-07 0 0" quat="1 0 0 0">
									<joint name="joint_LPedicel" class="nmf" type="hinge" pos="0 0 0" axis="0 1 0" stiffness="0.0" springref="0.0" damping="0.0001" frictionloss="0.0"/>
									<geom name="LPedicel" class="nmf" type="mesh" contype="0" conaffinity="0" condim="3" group="2" friction="1 0 0" solref="-1000000 -10000" margin="0.0" pos="0 0 0" quat="1 0 0 0" mesh="mesh_LPedicel" fluidcoef="0 0 0 0 0"/>
									<inertial pos="0.049508571624755859 0.0043900730088353157 -0.025609875097870827" mass="0.0008662544835547314" fullinertia="1.5192979294855612e-06 1.5709095209306909e-06 1.670157646412123e-06 8.524470593345203e-08 7.81641287753621e-08 -6.603283265879969e-08"/>
									<body name="LFuniculus_roll" pos="0.051315903663635254 -0.00017841905355453491 -0.042900562286376953" quat="1 0 0 0">
										<joint name="joint_LFuniculus_roll" class="nmf" type="hinge" pos="0 0 0" axis="0 0 1" stiffness="0.0" springref="0.0" damping="0.0001" frictionloss="0.0"/>
										<inertial pos="0 0 9.5367433061710472e-08" mass="0.0" fullinertia="1e-09 1e-09 1e-09 0.0 0.0 0.0"/>
										<body name="LFuniculus_yaw" pos="0 0 0" quat="1 0 0 0">
											<joint name="joint_LFuniculus_yaw" class="nmf" type="hinge" pos="0 0 0" axis="1 0 0" stiffness="0.0" springref="0.0" damping="0.0001" frictionloss="0.0"/>
											<inertial pos="0 0 9.5367433061710472e-08" mass="0.0" fullinertia="1e-09 1e-09 1e-09 0.0 0.0 0.0"/>
											<body name="LFuniculus" pos="0 0 0" quat="1 0 0 0">
												<joint name="joint_LFuniculus" class="nmf" type="hinge" pos="0 0 0" axis="0 1 0" stiffness="0.0" springref="0.0" damping="0.0001" frictionloss="0.0"/>
												<geom name="LFuniculus" class="nmf" type="mesh" contype="0" conaffinity="0" condim="3" group="2" friction="1 0 0" solref="-1000000 -10000" margin="0.0" pos="0 0 0" quat="1 0 0 0" mesh="mesh_LFuniculus" fluidcoef="0 0 0 0 0"/>
												<inertial pos="0.017254447564482689 -0.0072380127385258675 -0.091828919947147369" mass="0.0011002208214785619" fullinertia="3.0875132946578103e-06 2.865122963330836e-06 1.5824501346561423e-06 1.3156936484150013e-07 2.773538049999379e-07 -6.632120373927613e-09"/>
												<body name="LArista_roll" pos="0.019257545471191406 0.048715509474277496 -0.069890499114990234" quat="1 0 0 0">
													<joint name="joint_LArista_roll" class="nmf" type="hinge" pos="0 0 0" axis="0 0 1" stiffness="0.0" springref="0.0" damping="1e-05" frictionloss="0.0"/>
													<inertial pos="0 0 -1.9073486612342094e-07" mass="0.0" fullinertia="1e-09 1e-09 1e-09 0.0 0.0 0.0"/>
													<body name="LArista_yaw" pos="0 0 -2.384185791015625e-07" quat="1 0 0 0">
														<joint name="joint_LArista_yaw" class="nmf" type="hinge" pos="0 0 0" axis="1 0 0" stiffness="0.0" springref="0.0" damping="1e-05" frictionloss="0.0"/>
														<inertial pos="0 0 -9.5367433061710472e-08" mass="0.0" fullinertia="1e-09 1e-09 1e-09 0.0 0.0 0.0"/>
														<body name="LArista" pos="0 0 -2.384185791015625e-07" quat="1 0 0 0">
															<joint name="joint_LArista" class="nmf" type="hinge" pos="0 0 0" axis="0 1 0" stiffness="0.0" springref="0.0" damping="1e-05" frictionloss="0.0"/>
															<geom name="LArista" class="nmf" type="mesh" contype="0" conaffinity="0" condim="3" group="2" friction="0.29999999999999999 0 0" solref="-1000000 -10000" margin="0.0" pos="0 0 0" quat="1 0 0 0" mesh="mesh_LArista" fluidcoef="0 0 0 0 0"/>
															<inertial pos="0.015042114071547985 0.083989463746547699 0.014218616299331188" mass="0.00011001493090684334" fullinertia="4.65996884660329e-07 3.7042770364287426e-08 4.4883186581701936e-07 -2.5237243253880455e-08 9.424481638771289e-09 3.1652690957340936e-08"/>
														</body>
													</body>
												</body>
											</body>
										</body>
									</body>
								</body>
							</body>
						</body>
						<body name="REye" pos="0.23149150609970093 -0.0005665309727191925 0.017043113708496094" quat="1 0 0 0">
							<geom name="REye" class="nmf" type="mesh" contype="0" conaffinity="0" condim="3" group="2" friction="0 0 0" solref="-1000000 -10000" margin="0.0" pos="0 0 0" quat="1 0 0 0" mesh="mesh_REye"/>
							<inertial pos="-0.0029275417327880859 -0.30983772873878479 -0.02660980261862278" mass="0.010853648330100224" fullinertia="0.0001527984675925129 0.0002141083530535221 0.00010457337871355459 -2.6946246922124965e-05 1.8822428726680307e-05 1.0351807208739373e-05"/>
						</body>
						<body name="Rostrum" pos="0.43001961708068848 0.003381817601621151 -0.27448439598083496" quat="1 0 0 0">
							<geom name="Rostrum" class="nmf" type="mesh" contype="0" conaffinity="0" condim="3" group="2" friction="0 0 0" solref="-1000000 -10000" margin="0.0" pos="0 0 0" quat="1 0 0 0" mesh="mesh_Rostrum"/>
							<inertial pos="-0.17565731704235077 0.0041176388040184975 -0.017972946166992188" mass="0.01821516305100949" fullinertia="0.00024548290045259025 0.0002870465698828567 0.0002508260491576909 7.276993586326372e-08 1.5555772202121328e-06 8.363548928350972e-08"/>
							<body name="Haustellum" pos="-0.37093329429626465 0.000466151162981987 -0.019629240036010742" quat="1 0 0 0">
								<geom name="Haustellum" class="nmf" type="mesh" contype="0" conaffinity="0" condim="3" group="2" friction="0 0 0" solref="-1000000 -10000" margin="0.0" pos="0 0 0" quat="1 0 0 0" mesh="mesh_Haustellum"/>
								<inertial pos="0.18446870148181915 0.00591269601136446 -0.099196150898933411" mass="0.008088172523948103" fullinertia="6.459751752488199e-05 6.86134072562781e-05 8.594500414242766e-05 -3.178514766701578e-07 1.4620935977416919e-05 -5.438383791288974e-07"/>
							</body>
						</body>
						<body name="RPedicel_roll" pos="0.4287382960319519 -0.081443209201097488 0.082798361778259277" quat="1 0 0 0">
							<joint name="joint_RPedicel_roll" class="nmf" type="hinge" pos="0 0 0" axis="0 0 1" stiffness="0.0" springref="0.0" damping="0.0001" frictionloss="0.0"/>
							<inertial pos="9.5367433061710472e-08 0 0" mass="0.0" fullinertia="1e-09 1e-09 1e-09 0.0 0.0 0.0"/>
							<body name="RPedicel_yaw" pos="1.1920928955078125e-07 0 0" quat="1 0 0 0">
								<joint name="joint_RPedicel_yaw" class="nmf" type="hinge" pos="0 0 0" axis="1 0 0" stiffness="0.0" springref="0.0" damping="0.0001" frictionloss="0.0"/>
								<inertial pos="9.5367433061710472e-08 0 0" mass="0.0" fullinertia="1e-09 1e-09 1e-09 0.0 0.0 0.0"/>
								<body name="RPedicel" pos="1.1920928955078125e-07 0 0" quat="1 0 0 0">
									<joint name="joint_RPedicel" class="nmf" type="hinge" pos="0 0 0" axis="0 1 0" stiffness="0.0" springref="0.0" damping="0.0001" frictionloss="0.0"/>
									<geom name="RPedicel" class="nmf" type="mesh" contype="0" conaffinity="0" condim="3" group="2" friction="1 0 0" solref="-1000000 -10000" margin="0.0" pos="0 0 0" quat="1 0 0 0" mesh="mesh_RPedicel" fluidcoef="0 0 0 0 0"/>
									<inertial pos="0.04849548265337944 -0.0066871880553662777 -0.027813339605927467" mass="0.0008621888354241637" fullinertia="1.5038017044329922e-06 1.5560727064926338e-06 1.6669160745867685e-06 -8.683551221624438e-08 7.213894818482638e-08 6.113910611311166e-08"/>
									<body name="RFuniculus_roll" pos="0.050687968730926514 0.00094661861658096313 -0.04530024528503418" quat="1 0 0 0">
										<joint name="joint_RFuniculus_roll" class="nmf" type="hinge" pos="0 0 0" axis="0 0 1" stiffness="0.0" springref="0.0" damping="0.0001" frictionloss="0.0"/>
										<inertial pos="0 -1.1920929132713809e-08 -9.5367433061710472e-08" mass="0.0" fullinertia="1e-09 1e-09 1e-09 0.0 0.0 0.0"/>
										<body name="RFuniculus_yaw" pos="0 -1.4901161193847656e-08 0" quat="1 0 0 0">
											<joint name="joint_RFuniculus_yaw" class="nmf" type="hinge" pos="0 0 0" axis="1 0 0" stiffness="0.0" springref="0.0" damping="0.0001" frictionloss="0.0"/>
											<inertial pos="0 -1.1920929132713809e-08 -9.5367433061710472e-08" mass="0.0" fullinertia="1e-09 1e-09 1e-09 0.0 0.0 0.0"/>
											<body name="RFuniculus" pos="0 -1.4901161193847656e-08 0" quat="1 0 0 0">
												<joint name="joint_RFuniculus" class="nmf" type="hinge" pos="0 0 0" axis="0 1 0" stiffness="0.0" springref="0.0" damping="0.0001" frictionloss="0.0"/>
												<geom name="RFuniculus" class="nmf" type="mesh" contype="0" conaffinity="0" condim="3" group="2" friction="1 0 0" solref="-1000000 -10000" margin="0.0" pos="0 0 0" quat="1 0 0 0" mesh="mesh_RFuniculus" fluidcoef="0 0 0 0 0"/>
												<inertial pos="0.017940713092684746 0.0040577114559710026 -0.090368561446666718" mass="0.0010970476498469153" fullinertia="3.075666102885866e-06 2.82801880553117e-06 1.583608848172615e-06 -1.1520395853300368e-07 2.9046155983820534e-07 1.8747938587181156e-08"/>
												<body name="RArista_roll" pos="0.020437002182006836 -0.058991238474845886 -0.066675066947937012" quat="1 0 0 0">
													<joint name="joint_RArista_roll" class="nmf" type="hinge" pos="0 0 0" axis="0 0 1" stiffness="0.0" springref="0.0" damping="1e-05" frictionloss="0.0"/>
													<inertial pos="0 -1.1920929132713809e-08 0" mass="0.0" fullinertia="1e-09 1e-09 1e-09 0.0 0.0 0.0"/>
													<body name="RArista_yaw" pos="0 -2.9802322387695312e-08 0" quat="1 0 0 0">
														<joint name="joint_RArista_yaw" class="nmf" type="hinge" pos="0 0 0" axis="1 0 0" stiffness="0.0" springref="0.0" damping="1e-05" frictionloss="0.0"/>
														<inertial pos="0 -2.3841858265427618e-08 0" mass="0.0" fullinertia="1e-09 1e-09 1e-09 0.0 0.0 0.0"/>
														<body name="RArista" pos="0 -2.9802322387695312e-08 0" quat="1 0 0 0">
															<joint name="joint_RArista" class="nmf" type="hinge" pos="0 0 0" axis="0 1 0" stiffness="0.0" springref="0.0" damping="1e-05" frictionloss="0.0"/>
															<geom name="RArista" class="nmf" type="mesh" contype="0" conaffinity="0" condim="3" group="2" friction="0.29999999999999999 0 0" solref="-1000000 -10000" margin="0.0" pos="0 0 0" quat="1 0 0 0" mesh="mesh_RArista" fluidcoef="0 0 0 0 0"/>
															<inertial pos="0.018207645043730736 -0.07643195241689682 0.015183830633759499" mass="0.0001099907640123722" fullinertia="4.670162842313207e-07 3.705234323388251e-08 4.46609655191164e-07 -3.727948514978886e-09 -7.750596272503876e-09 -4.0081398195159985e-08"/>
														</body>
													</body>
												</body>
											</body>
										</body>
									</body>
								</body>
							</body>
						</body>
					</body>
				</body>
			</body>
			<body name="LFCoxa_roll" pos="-0.16154563426971436 0.16951037384569645 -0.23035943508148193" quat="1 0 0 0">
				<joint name="joint_LFCoxa_roll" class="nmf" type="hinge" pos="0 0 0" axis="0 0 1" stiffness="0.0" springref="0.0" damping="0.1" frictionloss="0.0"/>
				<inertial pos="-4.7683716530855236e-08 -1.1920929132713809e-08 0" mass="0.0" fullinertia="1e-09 1e-09 1e-09 0.0 0.0 0.0"/>
				<body name="LFCoxa_yaw" pos="-5.9604644775390625e-08 -2.9802322387695312e-08 0" quat="1 0 0 0">
					<joint name="joint_LFCoxa_yaw" class="nmf" type="hinge" pos="0 0 0" axis="1 0 0" stiffness="0.0" springref="0.0" damping="0.01" frictionloss="0.0"/>
					<inertial pos="-2.3841858265427618e-08 -2.3841858265427618e-08 0" mass="0.0" fullinertia="1e-09 1e-09 1e-09 0.0 0.0 0.0"/>
					<body name="LFCoxa" pos="-5.9604644775390625e-08 -2.9802322387695312e-08 0" quat="1 0 0 0">
						<joint name="joint_LFCoxa" class="nmf" type="hinge" pos="0 0 0" axis="0 1 0" stiffness="0.0" springref="0.0" damping="0.01" frictionloss="0.0"/>
						<geom name="LFCoxa" class="nmf" type="mesh" contype="0" conaffinity="0" condim="3" group="2" friction="1 0 0" solref="-1000000 -10000" margin="0.0" pos="0 0 0" quat="1 0 0 0" mesh="mesh_LFCoxa" fluidcoef="0 0 0 0 0"/>
						<inertial pos="0.011279130354523659 0.00736581115052104 -0.22946958243846893" mass="0.0045220040662493355" fullinertia="4.712381276042184e-05 4.552723677304267e-05 1.1321591847687633e-05 -1.2274809906478531e-06 -7.236545004123644e-07 -3.1069120896910145e-06"/>
						<body name="LFFemur" pos="-0.00060492753982543945 -0.0020639747381210327 -0.36546182632446289" quat="1 0 0 0">
							<joint name="joint_LFFemur" class="nmf" type="hinge" pos="0 0 0" axis="0 1 0" stiffness="0.0" springref="0.0" damping="0.01" frictionloss="0.0"/>
							<geom name="LFFemur" class="nmf" type="mesh" contype="0" conaffinity="0" condim="3" group="2" friction="1 0 0" solref="-1000000 -10000" margin="0.0" pos="0 0 0" quat="1 0 0 0" mesh="mesh_LFFemur" fluidcoef="0 0 0 0 0"/>
							<inertial pos="-0.010954642668366432 0.021125424653291702 -0.39625737071037292" mass="0.006294365178570592" fullinertia="0.0002157370788958023 0.00021478270450182665 1.1870386019150603e-05 1.6798094458189904e-07 6.785494849560672e-06 8.097484245651735e-06"/>
							<body name="LFFemur_roll" pos="-5.9604644775390625e-08 0 -1.1920928955078125e-07" quat="1 0 0 0">
								<joint name="joint_LFFemur_roll" class="nmf" type="hinge" pos="0 0 0" axis="0 0 1" stiffness="0.0" springref="0.0" damping="0.01" frictionloss="0.0"/>
								<inertial pos="-2.3841858265427618e-08 0 -4.7683716530855236e-08" mass="0.0" fullinertia="1e-09 1e-09 1e-09 0.0 0.0 0.0"/>
								<body name="LFTibia" pos="-0.0036284923553466797 -0.0010989010334014893 -0.70523034641519189" quat="1 0 0 0">
									<joint name="joint_LFTibia" class="nmf" type="hinge" pos="0 0 0" axis="0 1 0" stiffness="0.0" springref="0.0" damping="0.01" frictionloss="0.0"/>
									<geom name="LFTibia" class="nmf" type="mesh" contype="0" conaffinity="0" condim="3" group="2" friction="2 0 0" solref="-1000000 -10000" margin="0.0" pos="0 0 0" quat="1 0 0 0" mesh="mesh_LFTibia" fluidcoef="0 0 0 0 0"/>
									<inertial pos="0.02392880991101265 0.0099955322220921516 -0.31698378920555115" mass="0.002068820618721865" fullinertia="4.349762781915375e-05 4.32092083349527e-05 1.8270032944757237e-06 -6.181494636902154e-08 -1.4959013917518377e-06 -2.6989472254788085e-06"/>
									<body name="LFTarsus1" pos="-0.00032007694244384766 -0.00055192410945892334 -0.51838202169165015" quat="1 0 0 0">
										<joint name="joint_LFTarsus1" class="nmf" type="hinge" pos="0 0 0" axis="0 1 0" stiffness="0.0" springref="0.0" damping="0.1" frictionloss="0.0"/>
										<geom name="LFTarsus1" class="nmf" type="mesh" contype="0" conaffinity="0" condim="3" group="2" friction="2 0 0" solref="-1000000 -10000" margin="0.0" pos="0 0 0" quat="1 0 0 0" mesh="mesh_LFTarsus1" fluidcoef="0 0 0 0 0"/>
										<inertial pos="0.0082519054412841797 -0.003517496632412076 -0.13727636635303497" mass="0.00046485113319033296" fullinertia="2.0964557645231633e-06 2.1015949262804585e-06 1.7041431929651966e-07 6.905523364874082e-09 6.67638794806305e-08 -6.668363668596476e-08"/>
										<body name="LFTarsus2" pos="0.0014775395393371582 -0.00082576274871826172 -0.22551143169403076" quat="1 0 0 0">
											<joint name="joint_LFTarsus2" class="nmf" type="hinge" pos="0 0 0" axis="0 1 0" stiffness="0.0" springref="0.0" damping="0.1" frictionloss="0.0"/>
											<geom name="LFTarsus2" class="nmf" type="mesh" contype="0" conaffinity="0" condim="3" group="2" friction="2 0 0" solref="-1000000 -10000" margin="0.0" pos="0 0 0" quat="1 0 0 0" mesh="mesh_LFTarsus2" fluidcoef="0 0 0 0 0"/>
											<inertial pos="0.010072923265397549 -0.00325603480450809 -0.10305414348840714" mass="0.00020941328890791868" fullinertia="4.019227174557306e-07 4.022095214334457e-07 5.296160793523726e-08 3.234116485489335e-09 -1.7667517716669274e-08 -9.434757704674358e-09"/>
											<body name="LFTarsus3" pos="0.00091886520385742188 -1.1622905731201172e-06 -0.15366756916046143" quat="1 0 0 0">
												<joint name="joint_LFTarsus3" class="nmf" type="hinge" pos="0 0 0" axis="0 1 0" stiffness="0.0" springref="0.0" damping="0.1" frictionloss="0.0"/>
												<geom name="LFTarsus3" class="nmf" type="mesh" contype="0" conaffinity="0" condim="3" group="2" friction="2 0 0" solref="-1000000 -10000" margin="0.0" pos="0 0 0" quat="1 0 0 0" mesh="mesh_LFTarsus3" fluidcoef="0 0 0 0 0"/>
												<inertial pos="0.0093610528856515884 -0.0044113993644714355 -0.073273085057735443" mass="0.00011851731000018944" fullinertia="1.0194155123381958e-07 1.022646707036408e-07 2.540825528836891e-08 1.1463153314968054e-09 -5.84634686474954e-09 9.108161146489047e-10"/>
												<body name="LFTarsus4" pos="0.0013435184955596924 0.00041842460632324219 -0.098489820957183838" quat="1 0 0 0">
													<joint name="joint_LFTarsus4" class="nmf" type="hinge" pos="0 0 0" axis="0 1 0" stiffness="0.0" springref="0.0" damping="0.1" frictionloss="0.0"/>
													<geom name="LFTarsus4" class="nmf" type="mesh" contype="0" conaffinity="0" condim="3" group="2" friction="2 0 0" solref="-1000000 -10000" margin="0.0" pos="0 0 0" quat="1 0 0 0" mesh="mesh_LFTarsus4" fluidcoef="0 0 0 0 0"/>
													<inertial pos="0.00069010257720947266 -0.0050250054337084293 -0.063922695815563202" mass="9.269679574872209e-05" fullinertia="5.965720248338186e-08 6.005451066236795e-08 1.7947946662487982e-08 8.035855258322787e-10 -3.2838846874856543e-09 4.520752673761952e-10"/>
													<body name="LFTarsus5" pos="0.0014019608497619629 -0.00017428398132324219 -0.086987495422363281" quat="1 0 0 0">
														<joint name="joint_LFTarsus5" class="nmf" type="hinge" pos="0 0 0" axis="0 1 0" stiffness="0.0" springref="0.0" damping="0.1" frictionloss="0.0"/>
														<geom name="LFTarsus5" class="nmf" type="mesh" contype="0" conaffinity="0" condim="3" group="2" friction="2 0 0" solref="-1000000 -10000" margin="0.0" pos="0 0 0" quat="1 0 0 0" mesh="mesh_LFTarsus5" fluidcoef="0 0 0 0 0"/>
														<inertial pos="0.0020870447624474764 -0.0064410450868308544 -0.066006660461425781" mass="0.00011454791813432703" fullinertia="8.974932390550926e-08 9.446370323268723e-08 2.7014405441458504e-08 -1.356509774373254e-09 -6.8168972448890605e-09 -6.414270718165236e-10"/>
													</body>
												</body>
											</body>
										</body>
									</body>
								</body>
							</body>
						</body>
					</body>
				</body>
			</body>
			<body name="LHaltere_roll" pos="-0.80582523345947266 0.21355625428259373 -0.14926803112030029" quat="1 0 0 0">
				<inertial pos="0 2.3841858265427618e-08 -9.5367433061710472e-08" mass="0.0" fullinertia="1e-09 1e-09 1e-09 0.0 0.0 0.0"/>
				<body name="LHaltere_yaw" pos="0 2.9802322387695312e-08 0" quat="1 0 0 0">
					<inertial pos="0 0 -9.5367433061710472e-08" mass="0.0" fullinertia="1e-09 1e-09 1e-09 0.0 0.0 0.0"/>
					<body name="LHaltere" pos="0 2.9802322387695312e-08 0" quat="1 0 0 0">
						<geom name="LHaltere" class="nmf" type="mesh" contype="0" conaffinity="0" group="1" pos="0 0 0" quat="1 0 0 0" mesh="mesh_LHaltere"/>
						<inertial pos="-0.0221053846180439 0.21382319927215576 0.0095170978456735611" mass="0.0014161516439449334" fullinertia="1.401018605304313e-05 1.973116770280769e-06 1.3661075105086198e-05 3.200304890754385e-08 -6.835510003556702e-08 5.4829038721132187e-08"/>
					</body>
				</body>
			</body>
			<body name="LHCoxa_roll" pos="-0.78372153639793396 0.086993413046002388 -0.49661201238632202" quat="1 0 0 0">
				<joint name="joint_LHCoxa_roll" class="nmf" type="hinge" pos="0 0 0" axis="0 0 1" stiffness="0.0" springref="0.0" damping="0.01" frictionloss="0.0"/>
				<inertial pos="0 5.9604645663569045e-09 -9.5367433061710472e-08" mass="0.0" fullinertia="1e-09 1e-09 1e-09 0.0 0.0 0.0"/>
				<body name="LHCoxa_yaw" pos="0 0 0" quat="1 0 0 0">
					<joint name="joint_LHCoxa_yaw" class="nmf" type="hinge" pos="0 0 0" axis="1 0 0" stiffness="0.0" springref="0.0" damping="0.01" frictionloss="0.0"/>
					<inertial pos="0 5.9604645663569045e-09 -9.5367433061710472e-08" mass="0.0" fullinertia="1e-09 1e-09 1e-09 0.0 0.0 0.0"/>
					<body name="LHCoxa" pos="0 0 0" quat="1 0 0 0">
						<joint name="joint_LHCoxa" class="nmf" type="hinge" pos="0 0 0" axis="0 1 0" stiffness="0.0" springref="0.0" damping="0.01" frictionloss="0.0"/>
						<geom name="LHCoxa" class="nmf" type="mesh" contype="0" conaffinity="0" condim="3" group="2" friction="0 0 0" solref="-1000000 -10000" margin="0.0" pos="0 0 0" quat="1 0 0 0" mesh="mesh_LHCoxa"/>
						<inertial pos="-0.01400837954133749 0.029449660331010818 -0.10787587612867355" mass="0.0025634613650929467" fullinertia="1.0638476565953335e-05 1.1408809600503282e-05 6.991796720489023e-06 1.2880243832325034e-07 -2.0741832621486397e-07 -1.7925794052614201e-06"/>
						<body name="LHFemur" pos="-0.00027471780776977539 -0.00015975534915924072 -0.19941717386245728" quat="1 0 0 0">
							<joint name="joint_LHFemur" class="nmf" type="hinge" pos="0 0 0" axis="0 1 0" stiffness="0.0" springref="0.0" damping="0.01" frictionloss="0.0"/>
							<geom name="LHFemur" class="nmf" type="mesh" contype="0" conaffinity="0" condim="3" group="2" friction="1 0 0" solref="-1000000 -10000" margin="0.0" pos="0 0 0" quat="1 0 0 0" mesh="mesh_LHFemur" fluidcoef="0 0 0 0 0"/>
							<inertial pos="0.022989988327026367 -0.0098384981974959373 -0.44595643877983093" mass="0.008752848223782955" fullinertia="0.000412749115928565 0.00041276958217961333 2.1336136144334237e-05 -2.7163455773064453e-06 -6.848698280796725e-06 -8.199244926354969e-06"/>
							<body name="LHFemur_roll" pos="0 0 0" quat="1 0 0 0">
								<joint name="joint_LHFemur_roll" class="nmf" type="hinge" pos="0 0 0" axis="0 0 1" stiffness="0.0" springref="0.0" damping="0.01" frictionloss="0.0"/>
								<inertial pos="0 0 0" mass="0.0" fullinertia="1e-09 1e-09 1e-09 0.0 0.0 0.0"/>
								<body name="LHTibia" pos="0.00013548135757446289 -8.58306884765625e-05 -0.83631375432014465" quat="1 0 0 0">
									<joint name="joint_LHTibia" class="nmf" type="hinge" pos="0 0 0" axis="0 1 0" stiffness="0.0" springref="0.0" damping="0.01" frictionloss="0.0"/>
									<geom name="LHTibia" class="nmf" type="mesh" contype="0" conaffinity="0" condim="3" group="2" friction="1 0 0" solref="-1000000 -10000" margin="0.0" pos="0 0 0" quat="1 0 0 0" mesh="mesh_LHTibia" fluidcoef="0 0 0 0 0"/>
									<inertial pos="0.013148284517228603 -0.0068488717079162598 -0.42460152506828308" mass="0.0033711467153216585" fullinertia="0.00010745207544560011 0.00010826390108452979 3.884556646609324e-06 7.0919780201332e-08 -5.498416829466785e-06 1.3154246181736999e-06"/>
									<body name="LHTarsus1" pos="0.0002600252628326416 -0.00040558725595474243 -0.68445554375648499" quat="1 0 0 0">
										<joint name="joint_LHTarsus1" class="nmf" type="hinge" pos="0 0 0" axis="0 1 0" stiffness="0.0" springref="0.0" damping="0.1" frictionloss="0.0"/>
										<geom name="LHTarsus1" class="nmf" type="mesh" contype="0" conaffinity="0" condim="3" group="2" friction="2 0 0" solref="-1000000 -10000" margin="0.0" pos="0 0 0" quat="1 0 0 0" mesh="mesh_LHTarsus1" fluidcoef="0 0 0 0 0"/>
										<inertial pos="-0.012777209281921387 0.012578213587403297 -0.1745121031999588" mass="0.0010435290417843564" fullinertia="1.0903900418592264e-05 1.0993954193822944e-05 5.814418697712265e-07 6.46396683468496e-09 1.086556696735295e-07 -8.562483158412907e-08"/>
										<body name="LHTarsus2" pos="-5.8799982070922852e-05 0.0007624700665473938 -0.35274249315261841" quat="1 0 0 0">
											<joint name="joint_LHTarsus2" class="nmf" type="hinge" pos="0 0 0" axis="0 1 0" stiffness="0.0" springref="0.0" damping="0.1" frictionloss="0.0"/>
											<geom name="LHTarsus2" class="nmf" type="mesh" contype="0" conaffinity="0" condim="3" group="2" friction="2 0 0" solref="-1000000 -10000" margin="0.0" pos="0 0 0" quat="1 0 0 0" mesh="mesh_LHTarsus2" fluidcoef="0 0 0 0 0"/>
											<inertial pos="-0.011517978273332119 0.010785931721329689 -0.098260693252086639" mass="0.00035169703880210383" fullinertia="9.782862425137728e-07 9.83030014229675e-07 1.2488389564932046e-07 -3.0816774534172854e-09 -1.938481807738283e-08 2.578149242202161e-08"/>
											<body name="LHTarsus3" pos="1.9490718841552734e-05 -0.00090782344341278076 -0.17505311965942383" quat="1 0 0 0">
												<joint name="joint_LHTarsus3" class="nmf" type="hinge" pos="0 0 0" axis="0 1 0" stiffness="0.0" springref="0.0" damping="0.1" frictionloss="0.0"/>
												<geom name="LHTarsus3" class="nmf" type="mesh" contype="0" conaffinity="0" condim="3" group="2" friction="2 0 0" solref="-1000000 -10000" margin="0.0" pos="0 0 0" quat="1 0 0 0" mesh="mesh_LHTarsus3" fluidcoef="0 0 0 0 0"/>
												<inertial pos="-0.014321041293442249 0.011688000522553921 -0.055696107447147369" mass="0.00013524270807158196" fullinertia="1.236873861262903e-07 1.2583042861406471e-07 3.3279992866551566e-08 -1.2441728549747047e-09 -6.393467191604951e-10 9.665689375018886e-10"/>
												<body name="LHTarsus4" pos="6.4074993133544922e-06 0.00098983198404312134 -0.096707820892333984" quat="1 0 0 0">
													<joint name="joint_LHTarsus4" class="nmf" type="hinge" pos="0 0 0" axis="0 1 0" stiffness="0.0" springref="0.0" damping="0.1" frictionloss="0.0"/>
													<geom name="LHTarsus4" class="nmf" type="mesh" contype="0" conaffinity="0" condim="3" group="2" friction="2 0 0" solref="-1000000 -10000" margin="0.0" pos="0 0 0" quat="1 0 0 0" mesh="mesh_LHTarsus4" fluidcoef="0 0 0 0 0"/>
													<inertial pos="0 0 0" mass="9.012496547607396e-05" fullinertia="2.585993847354424e-07 2.6537498616290115e-07 4.589319969225213e-08 1.2389534956523486e-08 -5.950720020444117e-08 4.444977667339308e-08"/>
													<body name="LHTarsus5" pos="7.1853399276733398e-05 -0.00022908300161361694 -0.073304176330566406" quat="1 0 0 0">
														<joint name="joint_LHTarsus5" class="nmf" type="hinge" pos="0 0 0" axis="0 1 0" stiffness="0.0" springref="0.0" damping="0.1" frictionloss="0.0"/>
														<geom name="LHTarsus5" class="nmf" type="mesh" contype="0" conaffinity="0" condim="3" group="2" friction="2 0 0" solref="-1000000 -10000" margin="0.0" pos="0 0 0" quat="1 0 0 0" mesh="mesh_LHTarsus5" fluidcoef="0 0 0 0 0"/>
														<inertial pos="-0.011947560124099255 0.0081241074949502945 -0.059480667114257812" mass="0.00012468543442329056" fullinertia="1.018035140267619e-07 1.0573634101357342e-07 3.406053250191823e-08 -2.7882014577412392e-09 -4.517740657029234e-09 -1.3081147151276896e-09"/>
													</body>
												</body>
											</body>
										</body>
									</body>
								</body>
							</body>
						</body>
					</body>
				</body>
			</body>
			<body name="LMCoxa_roll" pos="-0.55687103420495987 0.12490093149244785 -0.48220914602279663" quat="1 0 0 0">
				<joint name="joint_LMCoxa_roll" class="nmf" type="hinge" pos="0 0 0" axis="0 0 1" stiffness="0.0" springref="0.0" damping="0.01" frictionloss="0.0"/>
				<inertial pos="0 0 1.9073486612342094e-07" mass="0.0" fullinertia="1e-09 1e-09 1e-09 0.0 0.0 0.0"/>
				<body name="LMCoxa_yaw" pos="0 -1.4901161193847656e-08 2.384185791015625e-07" quat="1 0 0 0">
					<joint name="joint_LMCoxa_yaw" class="nmf" type="hinge" pos="0 0 0" axis="1 0 0" stiffness="0.0" springref="0.0" damping="0.01" frictionloss="0.0"/>
					<inertial pos="0 0 9.5367433061710472e-08" mass="0.0" fullinertia="1e-09 1e-09 1e-09 0.0 0.0 0.0"/>
					<body name="LMCoxa" pos="0 -1.4901161193847656e-08 2.384185791015625e-07" quat="1 0 0 0">
						<joint name="joint_LMCoxa" class="nmf" type="hinge" pos="0 0 0" axis="0 1 0" stiffness="0.0" springref="0.0" damping="0.01" frictionloss="0.0"/>
						<geom name="LMCoxa" class="nmf" type="mesh" contype="0" conaffinity="0" condim="3" group="2" friction="0 0 0" solref="-1000000 -10000" margin="0.0" pos="0 0 0" quat="1 0 0 0" mesh="mesh_LMCoxa"/>
						<inertial pos="-0.0055065634660422802 0.013313400559127331 -0.095957234501838684" mass="0.0025958093133598816" fullinertia="1.2710284618152902e-05 1.184295156856155e-05 8.299395204176e-06 4.0878273320730403e-08 -3.5048600608243163e-07 -3.5370026791912912e-06"/>
						<body name="LMFemur" pos="-0.00021589547395706177 0.00014557689428329468 -0.18144667148590088" quat="1 0 0 0">
							<joint name="joint_LMFemur" class="nmf" type="hinge" pos="0 0 0" axis="0 1 0" stiffness="0.0" springref="0.0" damping="0.01" frictionloss="0.0"/>
							<geom name="LMFemur" class="nmf" type="mesh" contype="0" conaffinity="0" condim="3" group="2" friction="1 0 0" solref="-1000000 -10000" margin="0.0" pos="0 0 0" quat="1 0 0 0" mesh="mesh_LMFemur" fluidcoef="0 0 0 0 0"/>
							<inertial pos="0.019349096342921257 0.010498297400772572 -0.42227038741111755" mass="0.006482330598202185" fullinertia="0.0003228213529410159 0.0003229199172683516 1.073682855038871e-05 7.980359684732398e-08 -1.1450833285265944e-06 -2.8810764707616675e-06"/>
							<body name="LMFemur_roll" pos="-7.4505805969238281e-09 1.4901161193847656e-08 0" quat="1 0 0 0">
								<joint name="joint_LMFemur_roll" class="nmf" type="hinge" pos="0 0 0" axis="0 0 1" stiffness="0.0" springref="0.0" damping="0.01" frictionloss="0.0"/>
								<inertial pos="-5.9604645663569045e-09 1.1920929132713809e-08 0" mass="0.0" fullinertia="1e-09 1e-09 1e-09 0.0 0.0 0.0"/>
								<body name="LMTibia" pos="-0.00096974149346351624 0.00032547861337661743 -0.78366953134536743" quat="1 0 0 0">
									<joint name="joint_LMTibia" class="nmf" type="hinge" pos="0 0 0" axis="0 1 0" stiffness="0.0" springref="0.0" damping="0.01" frictionloss="0.0"/>
									<geom name="LMTibia" class="nmf" type="mesh" contype="0" conaffinity="0" condim="3" group="2" friction="1 0 0" solref="-1000000 -10000" margin="0.0" pos="0 0 0" quat="1 0 0 0" mesh="mesh_LMTibia" fluidcoef="0 0 0 0 0"/>
									<inertial pos="0.018114423379302025 0.012055421248078346 -0.39092212915420532" mass="0.002860094524149851" fullinertia="0.00010594110786564213 0.00010601479603137317 2.6255408506593383e-06 -2.3250287128312514e-07 -5.627270902197579e-06 -1.8027992555059153e-06"/>
									<body name="LMTarsus1" pos="0.00027941539883613586 0.00032790005207061768 -0.66732656955718994" quat="1 0 0 0">
										<joint name="joint_LMTarsus1" class="nmf" type="hinge" pos="0 0 0" axis="0 1 0" stiffness="0.0" springref="0.0" damping="0.1" frictionloss="0.0"/>
										<geom name="LMTarsus1" class="nmf" type="mesh" contype="0" conaffinity="0" condim="3" group="2" friction="2 0 0" solref="-1000000 -10000" margin="0.0" pos="0 0 0" quat="1 0 0 0" mesh="mesh_LMTarsus1" fluidcoef="0 0 0 0 0"/>
										<inertial pos="-0.011675506830215454 0.0086040860041975975 -0.17074728012084961" mass="0.0005247556124991491" fullinertia="3.773690679472309e-06 3.795778540969654e-06 1.8623278679936872e-07 1.075065609974808e-08 2.1411759803834006e-07 -7.402121730429064e-08"/>
										<body name="LMTarsus2" pos="0.00044655799865722656 -0.00057838112115859985 -0.29433631896972656" quat="1 0 0 0">
											<joint name="joint_LMTarsus2" class="nmf" type="hinge" pos="0 0 0" axis="0 1 0" stiffness="0.0" springref="0.0" damping="0.1" frictionloss="0.0"/>
											<geom name="LMTarsus2" class="nmf" type="mesh" contype="0" conaffinity="0" condim="3" group="2" friction="2 0 0" solref="-1000000 -10000" margin="0.0" pos="0 0 0" quat="1 0 0 0" mesh="mesh_LMTarsus2" fluidcoef="0 0 0 0 0"/>
											<inertial pos="-0.0090768039226531982 0.0092543363571166992 -0.096315480768680573" mass="0.0002354010887465768" fullinertia="4.786043317188043e-07 4.823458617188005e-07 6.398164695676348e-08 -9.282049291553926e-10 2.785301981099356e-09 -9.113750435706407e-09"/>
											<body name="LMTarsus3" pos="-9.112432599067688e-05 -0.00015010684728622437 -0.15916502475738525" quat="1 0 0 0">
												<joint name="joint_LMTarsus3" class="nmf" type="hinge" pos="0 0 0" axis="0 1 0" stiffness="0.0" springref="0.0" damping="0.1" frictionloss="0.0"/>
												<geom name="LMTarsus3" class="nmf" type="mesh" contype="0" conaffinity="0" condim="3" group="2" friction="2 0 0" solref="-1000000 -10000" margin="0.0" pos="0 0 0" quat="1 0 0 0" mesh="mesh_LMTarsus3" fluidcoef="0 0 0 0 0"/>
												<inertial pos="-0.006259542889893055 0.010509669780731201 -0.061798285692930222" mass="0.00011763119008566159" fullinertia="9.31605895819647e-08 9.370546346415634e-08 2.837357614235686e-08 1.3163413649873262e-09 -4.9509922135454605e-09 9.450966261032955e-10"/>
												<body name="LMTarsus4" pos="0.00022959709167480469 -0.00013905763626098633 -0.089734196662902832" quat="1 0 0 0">
													<joint name="joint_LMTarsus4" class="nmf" type="hinge" pos="0 0 0" axis="0 1 0" stiffness="0.0" springref="0.0" damping="0.1" frictionloss="0.0"/>
													<geom name="LMTarsus4" class="nmf" type="mesh" contype="0" conaffinity="0" condim="3" group="2" friction="2 0 0" solref="-1000000 -10000" margin="0.0" pos="0 0 0" quat="1 0 0 0" mesh="mesh_LMTarsus4" fluidcoef="0 0 0 0 0"/>
													<inertial pos="-5.9604645663569045e-09 -1.1920929132713809e-08 0" mass="6.844311672551235e-05" fullinertia="1.9736968486543227e-07 1.948953867252568e-07 2.4598037841061406e-08 4.4974445042902714e-09 -2.5910657687012627e-08 3.2530918022030886e-08"/>
													<body name="LMTarsus5" pos="0.00019349530339241028 7.4468553066253662e-05 -0.063277840614318848" quat="1 0 0 0">
														<joint name="joint_LMTarsus5" class="nmf" type="hinge" pos="0 0 0" axis="0 1 0" stiffness="0.0" springref="0.0" damping="0.1" frictionloss="0.0"/>
														<geom name="LMTarsus5" class="nmf" type="mesh" contype="0" conaffinity="0" condim="3" group="2" friction="2 0 0" solref="-1000000 -10000" margin="0.0" pos="0 0 0" quat="1 0 0 0" mesh="mesh_LMTarsus5" fluidcoef="0 0 0 0 0"/>
														<inertial pos="-0.0052026808261871338 0.0078973770141601562 -0.060198307037353516" mass="0.00011399435799447945" fullinertia="9.208656057284261e-08 9.60003759522206e-08 2.7438879714269946e-08 -1.4798401031464296e-09 -6.517996839476477e-09 -8.498870486507523e-10"/>
													</body>
												</body>
											</body>
										</body>
									</body>
								</body>
							</body>
						</body>
					</body>
				</body>
			</body>
			<body name="LWing_roll" pos="-0.54395866394042969 0.36983280815184116 0.18139433860778809" quat="0.7071067657322373 0 0 0.70710679664085752">
				<inertial pos="2.3841858265427618e-08 0 1.9073486612342094e-07" mass="0.0" fullinertia="1e-09 1e-09 1e-09 0.0 0.0 0.0"/>
				<body name="LWing_yaw" pos="-1.3322676295501878e-15 -2.9802322387695312e-08 2.384185791015625e-07" quat="0.98901586642260175 -0.14780939065008811 -1.143317297257293e-18 7.6501157495448676e-18">
					<inertial pos="0 -8.9406970715799616e-09 1.1175871605928478e-07" mass="0.0" fullinertia="1e-09 1e-09 1e-09 0.0 0.0 0.0"/>
					<body name="LWing" pos="-5.5511151231257827e-17 -6.9706836969274377e-08 2.2800082399854205e-07" quat="1 6.0639315691974794e-19 -1.2301927814936334e-42 -2.0287049209832048e-24">
						<geom name="LWing" class="nmf" type="mesh" contype="0" conaffinity="0" group="1" pos="0 0 0" quat="1 0 0 -1.4551916978336921e-15" mesh="mesh_LWing"/>
						<inertial pos="-0.10208909958600998 1.0870033502578735 0.11552351713180542" mass="0.0025000608094947188" fullinertia="0.0008023199765751854 0.00018091660454325854 0.0009475820336340257 -6.168955950489445e-05 4.102234610229562e-05 5.7378039073271316e-05"/>
					</body>
				</body>
			</body>
			<body name="RFCoxa_roll" pos="-0.15964537858963013 -0.17366563342511654 -0.23007118701934814" quat="1 0 0 0">
				<joint name="joint_RFCoxa_roll" class="nmf" type="hinge" pos="0 0 0" axis="0 0 1" stiffness="0.0" springref="0.0" damping="0.01" frictionloss="0.0"/>
				<inertial pos="0 -1.1920929132713809e-08 9.5367433061710472e-08" mass="0.0" fullinertia="1e-09 1e-09 1e-09 0.0 0.0 0.0"/>
				<body name="RFCoxa_yaw" pos="0 0 0" quat="1 0 0 0">
					<joint name="joint_RFCoxa_yaw" class="nmf" type="hinge" pos="0 0 0" axis="1 0 0" stiffness="0.0" springref="0.0" damping="0.01" frictionloss="0.0"/>
					<inertial pos="0 -1.1920929132713809e-08 9.5367433061710472e-08" mass="0.0" fullinertia="1e-09 1e-09 1e-09 0.0 0.0 0.0"/>
					<body name="RFCoxa" pos="0 0 0" quat="1 0 0 0">
						<joint name="joint_RFCoxa" class="nmf" type="hinge" pos="0 0 0" axis="0 1 0" stiffness="0.0" springref="0.0" damping="0.01" frictionloss="0.0"/>
						<geom name="RFCoxa" class="nmf" type="mesh" contype="0" conaffinity="0" condim="3" group="2" friction="1 0 0" solref="-1000000 -10000" margin="0.0" pos="0 0 0" quat="1 0 0 0" mesh="mesh_RFCoxa" fluidcoef="0 0 0 0 0"/>
						<inertial pos="0.0063267471268773079 0.0096058612689375877 -0.2294711172580719" mass="0.004522002437988243" fullinertia="4.712381322959321e-05 4.564099722317604e-05 1.1207818048204476e-05 1.2122635766321062e-06 -7.488590988989288e-07 2.397546545907319e-06"/>
						<body name="RFFemur" pos="-0.0030191540718078613 0.0013685822486877441 -0.36545079946517944" quat="1 0 0 0">
							<joint name="joint_RFFemur" class="nmf" type="hinge" pos="0 0 0" axis="0 1 0" stiffness="0.0" springref="0.0" damping="0.01" frictionloss="0.0"/>
							<geom name="RFFemur" class="nmf" type="mesh" contype="0" conaffinity="0" condim="3" group="2" friction="1 0 0" solref="-1000000 -10000" margin="0.0" pos="0 0 0" quat="1 0 0 0" mesh="mesh_RFFemur" fluidcoef="0 0 0 0 0"/>
							<inertial pos="-0.013492393307387829 -0.014454126358032227 -0.39591336250305176" mass="0.0062943760341217184" fullinertia="0.00021511689786095532 0.0002146555514453844 1.2621947948709673e-05 -9.493715079135706e-08 6.618823447631499e-06 -1.4846736094948131e-05"/>
							<body name="RFFemur_roll" pos="-5.9604644775390625e-08 0 0" quat="1 0 0 0">
								<joint name="joint_RFFemur_roll" class="nmf" type="hinge" pos="0 0 0" axis="0 0 1" stiffness="0.0" springref="0.0" damping="0.01" frictionloss="0.0"/>
								<inertial pos="-2.3841858265427618e-08 -1.1920929132713809e-08 -4.7683716530855236e-08" mass="0.0" fullinertia="1e-09 1e-09 1e-09 0.0 0.0 0.0"/>
								<body name="RFTibia" pos="-0.0056810081005096436 0.0018779933452606201 -0.70521488972008228" quat="1 0 0 0">
									<joint name="joint_RFTibia" class="nmf" type="hinge" pos="0 0 0" axis="0 1 0" stiffness="0.0" springref="0.0" damping="0.01" frictionloss="0.0"/>
									<geom name="RFTibia" class="nmf" type="mesh" contype="0" conaffinity="0" condim="3" group="2" friction="2 0 0" solref="-1000000 -10000" margin="0.0" pos="0 0 0" quat="1 0 0 0" mesh="mesh_RFTibia" fluidcoef="0 0 0 0 0"/>
									<inertial pos="0.023442937061190605 -0.017040228471159935 -0.31677436828613281" mass="0.0020688194360187592" fullinertia="4.3500474043375565e-05 4.330025580784303e-05 1.7329578085641428e-06 9.334765983202665e-08 -1.4941858114406243e-06 1.8393825588167648e-06"/>
									<body name="RFTarsus1" pos="3.2097101211547852e-05 0.0013511478900909424 -0.51841160468757153" quat="1 0 0 0">
										<camera name="camera_RFTarsus1_zoomin" class="nmf" mode="track" ipd="0.068" pos="-0.5 -2 0" euler="1.67 0 -0.3" fovy="60"/>
										<!--arctan(0.5/2) = 0.245 arctan(0.2/2) = 0.1 -->
										<joint name="joint_RFTarsus1" class="nmf" type="hinge" pos="0 0 0" axis="0 1 0" stiffness="0.0" springref="0.0" damping="0.1" frictionloss="0.0"/>
										<geom name="RFTarsus1" class="nmf" type="mesh" contype="0" conaffinity="0" condim="3" group="2" friction="2 0 0" solref="-1000000 -10000" margin="0.0" pos="0 0 0" quat="1 0 0 0" mesh="mesh_RFTarsus1" fluidcoef="0 0 0 0 0"/>
										<inertial pos="0.0074234963394701481 -0.011223316192626953 -0.13725867867469788" mass="0.00046485138504422503" fullinertia="2.0964549102399105e-06 2.103517921769806e-06 1.6849467410834598e-07 -5.535838007593591e-09 6.692101592624449e-08 2.704744167307905e-08"/>
										<body name="RFTarsus2" pos="0.0021611154079437256 0.0011281967163085938 -0.22541564702987671" quat="1 0 0 0">
											<joint name="joint_RFTarsus2" class="nmf" type="hinge" pos="0 0 0" axis="0 1 0" stiffness="0.0" springref="0.0" damping="0.1" frictionloss="0.0"/>
											<geom name="RFTarsus2" class="nmf" type="mesh" contype="0" conaffinity="0" condim="3" group="2" friction="2 0 0" solref="-1000000 -10000" margin="0.0" pos="0 0 0" quat="1 0 0 0" mesh="mesh_RFTarsus2" fluidcoef="0 0 0 0 0"/>
											<inertial pos="0.0085637336596846581 -0.015500927343964577 -0.10310168564319611" mass="0.00020941347570628473" fullinertia="4.019239015522629e-07 4.024501951292487e-07 5.2721185956788355e-08 -3.5956518916436902e-09 -1.7592281639831685e-08 2.26886923556319e-09"/>
											<body name="RFTarsus3" pos="0.0018048286437988281 0.00035412609577178955 -0.15366643667221069" quat="1 0 0 0">
												<joint name="joint_RFTarsus3" class="nmf" type="hinge" pos="0 0 0" axis="0 1 0" stiffness="0.0" springref="0.0" damping="0.1" frictionloss="0.0"/>
												<geom name="RFTarsus3" class="nmf" type="mesh" contype="0" conaffinity="0" condim="3" group="2" friction="2 0 0" solref="-1000000 -10000" margin="0.0" pos="0 0 0" quat="1 0 0 0" mesh="mesh_RFTarsus3" fluidcoef="0 0 0 0 0"/>
												<inertial pos="0.0069680693559348583 -0.017446447163820267 -0.073320485651493073" mass="0.00011851737405370074" fullinertia="1.01941803061229e-07 1.0219511470901431e-07 2.5477748433502503e-08 -1.2658881413813176e-09 -5.820494167939649e-09 -2.4852692203238403e-09"/>
												<body name="RFTarsus4" pos="0.0020432472229003906 -0.00018799304962158203 -0.098483145236968994" quat="1 0 0 0">
													<joint name="joint_RFTarsus4" class="nmf" type="hinge" pos="0 0 0" axis="0 1 0" stiffness="0.0" springref="0.0" damping="0.1" frictionloss="0.0"/>
													<geom name="RFTarsus4" class="nmf" type="mesh" contype="0" conaffinity="0" condim="3" group="2" friction="2 0 0" solref="-1000000 -10000" margin="0.0" pos="0 0 0" quat="1 0 0 0" mesh="mesh_RFTarsus4" fluidcoef="0 0 0 0 0"/>
													<inertial pos="0.0068747042678296566 -0.018890619277954102 -0.063961796462535858" mass="9.269690720771255e-05" fullinertia="5.965742982101057e-08 6.001842680828075e-08 1.798410850103533e-08 -8.707170040059447e-10 -3.266094544731243e-09 -1.3147009734854399e-09"/>
													<body name="RFTarsus5" pos="0.0020258724689483643 0.00025747716426849365 -0.086998105049133301" quat="1 0 0 0">
														<joint name="joint_RFTarsus5" class="nmf" type="hinge" pos="0 0 0" axis="0 1 0" stiffness="0.0" springref="0.0" damping="0.1" frictionloss="0.0"/>
														<geom name="RFTarsus5" class="nmf" type="mesh" contype="0" conaffinity="0" condim="3" group="2" friction="2 0 0" solref="-1000000 -10000" margin="0.0" pos="0 0 0" quat="1 0 0 0" mesh="mesh_RFTarsus5" fluidcoef="0 0 0 0 0"/>
														<inertial pos="0.0065568448044359684 -0.019383907318115234 -0.066049575805664062" mass="0.00011454814826407662" fullinertia="8.941826136516917e-08 9.480052964904585e-08 2.7009213345570873e-08 -5.08505680096278e-10 -6.7912072139120745e-09 -5.588522891139943e-10"/>
													</body>
												</body>
											</body>
										</body>
									</body>
								</body>
							</body>
						</body>
					</body>
				</body>
			</body>
			<body name="RHaltere_roll" pos="-0.80582511425018311 -0.21355666778981686 -0.1492685079574585" quat="1 0 0 0">
				<inertial pos="0 0 0" mass="0.0" fullinertia="1e-09 1e-09 1e-09 0.0 0.0 0.0"/>
				<body name="RHaltere_yaw" pos="0 0 0" quat="1 0 0 0">
					<inertial pos="0 0 0" mass="0.0" fullinertia="1e-09 1e-09 1e-09 0.0 0.0 0.0"/>
					<body name="RHaltere" pos="0 0 0" quat="1 0 0 0">
						<geom name="RHaltere" class="nmf" type="mesh" contype="0" conaffinity="0" group="1" pos="0 0 0" quat="1 0 0 0" mesh="mesh_RHaltere"/>
						<inertial pos="-0.022123051807284355 -0.19827540218830109 0.0072251320816576481" mass="0.0014161459875842643" fullinertia="1.4020029846150617e-05 1.973124440724455e-06 1.3650805979378972e-05 -1.1272894938793228e-08 3.2683329315348975e-08 -6.35447524631105e-08"/>
					</body>
				</body>
			</body>
			<body name="RHCoxa_roll" pos="-0.78372162580490112 -0.086993483826518059 -0.49661147594451904" quat="1 0 0 0">
				<joint name="joint_RHCoxa_roll" class="nmf" type="hinge" pos="0 0 0" axis="0 0 1" stiffness="0.0" springref="0.0" damping="0.01" frictionloss="0.0"/>
				<inertial pos="0 1.1920929132713809e-08 0" mass="0.0" fullinertia="1e-09 1e-09 1e-09 0.0 0.0 0.0"/>
				<body name="RHCoxa_yaw" pos="0 1.4901161193847656e-08 0" quat="1 0 0 0">
					<joint name="joint_RHCoxa_yaw" class="nmf" type="hinge" pos="0 0 0" axis="1 0 0" stiffness="0.0" springref="0.0" damping="0.01" frictionloss="0.0"/>
					<inertial pos="0 0 0" mass="0.0" fullinertia="1e-09 1e-09 1e-09 0.0 0.0 0.0"/>
					<body name="RHCoxa" pos="0 1.4901161193847656e-08 0" quat="1 0 0 0">
						<joint name="joint_RHCoxa" class="nmf" type="hinge" pos="0 0 0" axis="0 1 0" stiffness="0.0" springref="0.0" damping="0.01" frictionloss="0.0"/>
						<geom name="RHCoxa" class="nmf" type="mesh" contype="0" conaffinity="0" condim="3" group="2" friction="0 0 0" solref="-1000000 -10000" margin="0.0" pos="0 0 0" quat="1 0 0 0" mesh="mesh_RHCoxa"/>
						<inertial pos="-0.013914823532104492 -0.01245646458119154 -0.10789203643798828" mass="0.00256346618880083" fullinertia="1.0639120106914842e-05 1.1406619476540892e-05 6.993635863024491e-06 -1.300874846710679e-07 -2.032397693891712e-07 1.7954716488237949e-06"/>
						<body name="RHFemur" pos="-7.8380107879638672e-05 0.00029505789279937744 -0.19941705465316772" quat="1 0 0 0">
							<joint name="joint_RHFemur" class="nmf" type="hinge" pos="0 0 0" axis="0 1 0" stiffness="0.0" springref="0.0" damping="0.01" frictionloss="0.0"/>
							<geom name="RHFemur" class="nmf" type="mesh" contype="0" conaffinity="0" condim="3" group="2" friction="1 0 0" solref="-1000000 -10000" margin="0.0" pos="0 0 0" quat="1 0 0 0" mesh="mesh_RHFemur" fluidcoef="0 0 0 0 0"/>
							<inertial pos="0.022992277517914772 0.026323556900024414 -0.44598349928855896" mass="0.008752846411343817" fullinertia="0.00041275558502376175 0.00041277714481314793 2.1322423705105886e-05 2.7106582045798294e-06 -6.865783889453158e-06 7.85255938094972e-06"/>
							<body name="RHFemur_roll" pos="0 2.9802322387695312e-08 -1.1920928955078125e-07" quat="1 0 0 0">
								<joint name="joint_RHFemur_roll" class="nmf" type="hinge" pos="0 0 0" axis="0 0 1" stiffness="0.0" springref="0.0" damping="0.01" frictionloss="0.0"/>
								<inertial pos="0 2.3841858265427618e-08 -4.7683716530855236e-08" mass="0.0" fullinertia="1e-09 1e-09 1e-09 0.0 0.0 0.0"/>
								<body name="RHTibia" pos="8.1419944763183594e-05 -0.00067412108182907104 -0.8363138884305954" quat="1 0 0 0">
									<joint name="joint_RHTibia" class="nmf" type="hinge" pos="0 0 0" axis="0 1 0" stiffness="0.0" springref="0.0" damping="0.01" frictionloss="0.0"/>
									<geom name="RHTibia" class="nmf" type="mesh" contype="0" conaffinity="0" condim="3" group="2" friction="1 0 0" solref="-1000000 -10000" margin="0.0" pos="0 0 0" quat="1 0 0 0" mesh="mesh_RHTibia" fluidcoef="0 0 0 0 0"/>
									<inertial pos="0.01747598685324192 0.017848348245024681 -0.42461252212524414" mass="0.0033711512886318825" fullinertia="0.00010745154342410109 0.0001082639023470002 3.885718474981566e-06 8.303522206335814e-08 -5.661016352374624e-06 -1.8423064174591537e-07"/>
									<body name="RHTarsus1" pos="-0.00026181340217590332 0.00024248659610748291 -0.68445618450641632" quat="1 0 0 0">
										<joint name="joint_RHTarsus1" class="nmf" type="hinge" pos="0 0 0" axis="0 1 0" stiffness="0.0" springref="0.0" damping="0.1" frictionloss="0.0"/>
										<geom name="RHTarsus1" class="nmf" type="mesh" contype="0" conaffinity="0" condim="3" group="2" friction="2 0 0" solref="-1000000 -10000" margin="0.0" pos="0 0 0" quat="1 0 0 0" mesh="mesh_RHTarsus1" fluidcoef="0 0 0 0 0"/>
										<inertial pos="-0.013229799456894398 0.005408167839050293 -0.174530029296875" mass="0.0010435376475255117" fullinertia="1.0944047117063149e-05 1.0954541705561156e-05 5.81203070813038e-07 -4.5321601024775226e-08 1.245822396559083e-07 3.302331777437854e-08"/>
										<body name="RHTarsus2" pos="0.00025260448455810547 -0.00025808811187744141 -0.35274320840835571" quat="1 0 0 0">
											<joint name="joint_RHTarsus2" class="nmf" type="hinge" pos="0 0 0" axis="0 1 0" stiffness="0.0" springref="0.0" damping="0.1" frictionloss="0.0"/>
											<geom name="RHTarsus2" class="nmf" type="mesh" contype="0" conaffinity="0" condim="3" group="2" friction="2 0 0" solref="-1000000 -10000" margin="0.0" pos="0 0 0" quat="1 0 0 0" mesh="mesh_RHTarsus2" fluidcoef="0 0 0 0 0"/>
											<inertial pos="-0.011340809054672718 0.0059734880924224854 -0.098242759704589844" mass="0.00035169649688564567" fullinertia="9.826123228747592e-07 9.78999132010856e-07 1.245831122938035e-07 3.572227575468462e-09 -2.3346649601210263e-08 -1.540345176734388e-08"/>
											<body name="RHTarsus3" pos="0.00022739171981811523 -0.00039763003587722778 -0.17505478858947754" quat="1 0 0 0">
												<joint name="joint_RHTarsus3" class="nmf" type="hinge" pos="0 0 0" axis="0 1 0" stiffness="0.0" springref="0.0" damping="0.1" frictionloss="0.0"/>
												<geom name="RHTarsus3" class="nmf" type="mesh" contype="0" conaffinity="0" condim="3" group="2" friction="2 0 0" solref="-1000000 -10000" margin="0.0" pos="0 0 0" quat="1 0 0 0" mesh="mesh_RHTarsus3" fluidcoef="0 0 0 0 0"/>
												<inertial pos="-0.014224529266357422 0.0076322257518768311 -0.055587198585271835" mass="0.0001352428932360253" fullinertia="1.2633234246849736e-07 1.231450437798958e-07 3.332106169698795e-08 -3.316122311117378e-10 -2.197304468649647e-09 -5.570019419616638e-10"/>
												<body name="RHTarsus4" pos="-0.00051742792129516602 0.00032848119735717773 -0.096711039543151855" quat="1 0 0 0">
													<joint name="joint_RHTarsus4" class="nmf" type="hinge" pos="0 0 0" axis="0 1 0" stiffness="0.0" springref="0.0" damping="0.1" frictionloss="0.0"/>
													<geom name="RHTarsus4" class="nmf" type="mesh" contype="0" conaffinity="0" condim="3" group="2" friction="2 0 0" solref="-1000000 -10000" margin="0.0" pos="0 0 0" quat="1 0 0 0" mesh="mesh_RHTarsus4" fluidcoef="0 0 0 0 0"/>
													<inertial pos="0 0 9.5367433061710472e-08" mass="9.01249567179059e-05" fullinertia="2.530913905586701e-07 2.6555597773595455e-07 3.854376426429984e-08 8.50660615377095e-09 -5.6999152345403607e-08 3.012462504363183e-08"/>
													<body name="RHTarsus5" pos="0.00035637617111206055 -0.00034637749195098877 -0.073303103446960449" quat="1 0 0 0">
														<joint name="joint_RHTarsus5" class="nmf" type="hinge" pos="0 0 0" axis="0 1 0" stiffness="0.0" springref="0.0" damping="0.1" frictionloss="0.0"/>
														<geom name="RHTarsus5" class="nmf" type="mesh" contype="0" conaffinity="0" condim="3" group="2" friction="2 0 0" solref="-1000000 -10000" margin="0.0" pos="0 0 0" quat="1 0 0 0" mesh="mesh_RHTarsus5" fluidcoef="0 0 0 0 0"/>
														<inertial pos="-0.010403466410934925 0.0085104107856750488 -0.059466935694217682" mass="0.00012468550520191836" fullinertia="1.020736338199787e-07 1.0553073131320156e-07 3.399621043276154e-08 2.9093679976278777e-09 -3.2507830584509796e-09 2.6929686745873457e-09"/>
													</body>
												</body>
											</body>
										</body>
									</body>
								</body>
							</body>
						</body>
					</body>
				</body>
			</body>
			<body name="RMCoxa_roll" pos="-0.5568711943924427 -0.12490125559270382 -0.48220843076705933" quat="1 0 0 0">
				<joint name="joint_RMCoxa_roll" class="nmf" type="hinge" pos="0 0 0" axis="0 0 1" stiffness="0.0" springref="0.0" damping="0.01" frictionloss="0.0"/>
				<inertial pos="0 0 0" mass="0.0" fullinertia="1e-09 1e-09 1e-09 0.0 0.0 0.0"/>
				<body name="RMCoxa_yaw" pos="0 0 0" quat="1 0 0 0">
					<joint name="joint_RMCoxa_yaw" class="nmf" type="hinge" pos="0 0 0" axis="1 0 0" stiffness="0.0" springref="0.0" damping="0.01" frictionloss="0.0"/>
					<inertial pos="0 0 0" mass="0.0" fullinertia="1e-09 1e-09 1e-09 0.0 0.0 0.0"/>
					<body name="RMCoxa" pos="0 0 0" quat="1 0 0 0">
						<joint name="joint_RMCoxa" class="nmf" type="hinge" pos="0 0 0" axis="0 1 0" stiffness="0.0" springref="0.0" damping="0.01" frictionloss="0.0"/>
						<geom name="RMCoxa" class="nmf" type="mesh" contype="0" conaffinity="0" condim="3" group="2" friction="0 0 0" solref="-1000000 -10000" margin="0.0" pos="0 0 0" quat="1 0 0 0" mesh="mesh_RMCoxa"/>
						<inertial pos="-0.0055109085515141487 0.0036018968094140291 -0.095951750874519348" mass="0.0025958084153147034" fullinertia="1.2710285865574647e-05 1.184321294886986e-05 8.299112186827602e-06 -4.081786719877803e-08 -3.508004312686905e-07 3.5368295547059355e-06"/>
						<body name="RMFemur" pos="-0.00021554157137870789 -0.00015276670455932617 -0.18144673109054565" quat="1 0 0 0">
							<joint name="joint_RMFemur" class="nmf" type="hinge" pos="0 0 0" axis="0 1 0" stiffness="0.0" springref="0.0" damping="0.01" frictionloss="0.0"/>
							<geom name="RMFemur" class="nmf" type="mesh" contype="0" conaffinity="0" condim="3" group="2" friction="1 0 0" solref="-1000000 -10000" margin="0.0" pos="0 0 0" quat="1 0 0 0" mesh="mesh_RMFemur" fluidcoef="0 0 0 0 0"/>
							<inertial pos="0.019344603642821312 0.0067075970582664013 -0.42226895689964294" mass="0.006482327249565799" fullinertia="0.0003228210587073814 0.0003229154490521696 1.0740947552411523e-05 -7.902057192422091e-08 -1.1464607488585402e-06 3.0961938242818262e-06"/>
							<body name="RMFemur_roll" pos="0 0 -1.1920928955078125e-07" quat="1 0 0 0">
								<joint name="joint_RMFemur_roll" class="nmf" type="hinge" pos="0 0 0" axis="0 0 1" stiffness="0.0" springref="0.0" damping="0.01" frictionloss="0.0"/>
								<inertial pos="0 0 -4.7683716530855236e-08" mass="0.0" fullinertia="1e-09 1e-09 1e-09 0.0 0.0 0.0"/>
								<body name="RMTibia" pos="-0.00097177550196647644 0.00021497905254364014 -0.78366996347904205" quat="1 0 0 0">
									<joint name="joint_RMTibia" class="nmf" type="hinge" pos="0 0 0" axis="0 1 0" stiffness="0.0" springref="0.0" damping="0.01" frictionloss="0.0"/>
									<geom name="RMTibia" class="nmf" type="mesh" contype="0" conaffinity="0" condim="3" group="2" friction="1 0 0" solref="-1000000 -10000" margin="0.0" pos="0 0 0" quat="1 0 0 0" mesh="mesh_RMTibia" fluidcoef="0 0 0 0 0"/>
									<inertial pos="0.01062463503330946 0.0047764419578015804 -0.40760311484336853" mass="0.0028600997544055164" fullinertia="0.00010591554406326336 0.0001060195713142781 2.647140643151944e-06 2.32152222619666e-07 -5.849730838729992e-06 1.7109275105513768e-06"/>
									<body name="RMTarsus1" pos="-0.00014773383736610413 0.0010670721530914307 -0.6673261970281601" quat="1 0 0 0">
										<joint name="joint_RMTarsus1" class="nmf" type="hinge" pos="0 0 0" axis="0 1 0" stiffness="0.0" springref="0.0" damping="0.1" frictionloss="0.0"/>
										<geom name="RMTarsus1" class="nmf" type="mesh" contype="0" conaffinity="0" condim="3" group="2" friction="0 0 0" solref="-1000000 -10000" margin="0.0" pos="0 0 0" quat="1 0 0 0" mesh="mesh_RMTarsus1"/>
										<inertial pos="-0.018532484769821167 0.0066356658935546875 -0.18734894692897797" mass="0.000524756450411376" fullinertia="3.771063681742313e-06 3.795903517827869e-06 1.8875511393356142e-07 -1.1146514199825001e-08 2.3291529265968519e-07 7.813701988793483e-08"/>
										<body name="RMTarsus2" pos="0.00057838112115859985 -0.00038231909275054932 -0.28996920585632324" quat="1 0 0 0">
											<joint name="joint_RMTarsus2" class="nmf" type="hinge" pos="0 0 0" axis="0 1 0" stiffness="0.0" springref="0.0" damping="0.1" frictionloss="0.0"/>
											<geom name="RMTarsus2" class="nmf" type="mesh" contype="0" conaffinity="0" condim="3" group="2" friction="0 0 0" solref="-1000000 -10000" margin="0.0" pos="0 0 0" quat="1 0 0 0" mesh="mesh_RMTarsus2"/>
											<inertial pos="-0.014674968086183071 0.0079340105876326561 -0.11728506535291672" mass="0.0002354013998600498" fullinertia="4.785562712847655e-07 4.823458670388776e-07 6.403104876120106e-08 8.597072728156642e-10 4.886047518831537e-09 9.353103909535344e-09"/>
											<body name="RMTarsus3" pos="3.501400351524353e-05 0.00015558302402496338 -0.16015195846557617" quat="1 0 0 0">
												<joint name="joint_RMTarsus3" class="nmf" type="hinge" pos="0 0 0" axis="0 1 0" stiffness="0.0" springref="0.0" damping="0.1" frictionloss="0.0"/>
												<geom name="RMTarsus3" class="nmf" type="mesh" contype="0" conaffinity="0" condim="3" group="2" friction="0 0 0" solref="-1000000 -10000" margin="0.0" pos="0 0 0" quat="1 0 0 0" mesh="mesh_RMTarsus3"/>
												<inertial pos="-0.012899535708129406 0.0053047537803649902 -0.081616781651973724" mass="0.00011763144858436785" fullinertia="9.310275694416137e-08 9.351940145445196e-08 2.8617975683901036e-08 -1.3850133398001045e-09 -6.250355140900251e-09 -1.424930940656579e-09"/>
												<body name="RMTarsus4" pos="-0.00048250332474708557 0.00024263560771942139 -0.092435002326965332" quat="1 0 0 0">
													<joint name="joint_RMTarsus4" class="nmf" type="hinge" pos="0 0 0" axis="0 1 0" stiffness="0.0" springref="0.0" damping="0.1" frictionloss="0.0"/>
													<geom name="RMTarsus4" class="nmf" type="mesh" contype="0" conaffinity="0" condim="3" group="2" friction="0 0 0" solref="-1000000 -10000" margin="0.0" pos="0 0 0" quat="1 0 0 0" mesh="mesh_RMTarsus4"/>
													<inertial pos="0 0 9.5367433061710472e-08" mass="6.84432308676254e-05" fullinertia="3.301470692564722e-07 3.41408468374553e-07 3.0625741274269724e-08 6.689390170107107e-09 -6.552494466943857e-08 2.9099283338976596e-08"/>
													<body name="RMTarsus5" pos="0.00160989910364151 -0.00012277066707611084 -0.06372225284576416" quat="1 0 0 0">
														<joint name="joint_RMTarsus5" class="nmf" type="hinge" pos="0 0 0" axis="0 1 0" stiffness="0.0" springref="0.0" damping="0.1" frictionloss="0.0"/>
														<geom name="RMTarsus5" class="nmf" type="mesh" contype="0" conaffinity="0" condim="3" group="2" friction="0 0 0" solref="-1000000 -10000" margin="0.0" pos="0 0 0" quat="1 0 0 0" mesh="mesh_RMTarsus5"/>
														<inertial pos="-0.014021026901900768 0.0084944842383265495 -0.077146433293819427" mass="0.00011399464253693984" fullinertia="9.149102537295518e-08 9.645804467269863e-08 2.7578251117581608e-08 5.455660469550331e-10 -7.211201890463651e-09 1.4413404260868506e-10"/>
													</body>
												</body>
											</body>
										</body>
									</body>
								</body>
							</body>
						</body>
					</body>
				</body>
			</body>
			<body name="RWing_roll" pos="-0.5439588725566864 -0.369832968339324 0.18139410018920898" quat="0.7071067657322373 0 0 -0.70710679664085752">
				<inertial pos="0 0 0" mass="0.0" fullinertia="1e-09 1e-09 1e-09 0.0 0.0 0.0"/>
				<body name="RWing_yaw" pos="-1.27675647831893e-15 2.9802322387695312e-08 0" quat="0.98901586642260175 0.14780939065008811 -1.143317297257293e-18 -7.6501157495448676e-18">
					<inertial pos="0 0 -1.9371510617816057e-08" mass="0.0" fullinertia="1e-09 1e-09 1e-09 0.0 0.0 0.0"/>
					<body name="RWing" pos="0 0 0" quat="1 -6.0639315691974794e-19 -1.2301927814936334e-42 2.0287049209832048e-24">
						<geom name="RWing" class="nmf" type="mesh" contype="0" conaffinity="0" group="1" pos="0 0 0" quat="1 0 0 1.4551916978336921e-15" mesh="mesh_RWing"/>
						<inertial pos="-0.1000005230307579 -1.0700113773345947 0.11686674505472183" mass="0.002499939190505281" fullinertia="0.000810539961944582 0.00018097093612029778 0.000954179995811845 6.131926117128596e-05 4.251352752368089e-05 -5.685947285267354e-05"/>
					</body>
				</body>
			</body>
		</body>
		<light name="light_animat_top" class="nmf" mode="trackcom" directional="true" castshadow="false" active="true" pos="0 0 80" dir="0 0 -1" attenuation="0.5 0 0" cutoff="100.0" exponent="1.0" ambient="0.20000000000000001 0.20000000000000001 0.20000000000000001" diffuse="0.69999999999999996 0.69999999999999996 0.69999999999999996" specular="0.29999999999999999 0.29999999999999999 0.29999999999999999"/>
		<light name="light_animat_bottom" class="nmf" mode="trackcom" directional="true" castshadow="false" active="true" pos="0 0 -80" dir="0 0 1" attenuation="0.5 0 0" cutoff="100.0" exponent="1.0" ambient="0.20000000000000001 0.20000000000000001 0.20000000000000001" diffuse="0.69999999999999996 0.69999999999999996 0.69999999999999996" specular="0.29999999999999999 0.29999999999999999 0.29999999999999999"/>
		<camera name="camera_back" class="nmf" mode="fixed" ipd="0.068" pos="-8 0 1.0" euler="1.57 0.0 -1.57"/>
		<camera name="camera_back_track" class="nmf" mode="track" ipd="0.068" pos="-12 0 6" euler="1.2 0.0 -1.57"/>
		<camera name="camera_front" class="nmf" mode="fixed" ipd="0.068" pos="8 0 1.0" euler="1.57 0.0 1.57"/>
		<camera name="camera_left" class="nmf" mode="fixed" ipd="0.068" pos="0 8 1.0" euler="-1.57 3.14 0"/>
		<camera name="camera_right" class="nmf" mode="fixed" ipd="0.068" pos="0 -8 1.0" euler="1.57 0 0"/>
		<camera name="camera_top_right" class="nmf" mode="fixed" ipd="0.068" pos="0 -8 5" euler="1.1 0 0"/>
		<camera name="camera_top" class="nmf" mode="track" ipd="0.068" pos="0 0 8" euler="0 0 0"/>
		<camera name="camera_top_zoomout" class="nmf" mode="track" ipd="0.068" pos="0 0 40" euler="0 0 0"/>
		<camera name="camera_bottom" class="nmf" mode="track" ipd="0.068" pos="0 0 -8" euler="0 3.14 0"/>
		<camera name="camera_right_front" class="nmf" mode="track" ipd="0.068" pos="4 -6 1.0" euler="1.57 0 0.588"/>
		<!-- arctan(2/3) = 0.588 -->
		<camera name="camera_left_top_zoomout" class="nmf" mode="track" ipd="0.068" pos="0 8 5" euler="-2.129 3.14 0"/>
		<!-- arctan(5/8) = 0.559  -1.57 - 0.559 = -2.129 -->
		<camera name="camera_right_top_zoomout" class="nmf" mode="track" ipd="0.068" pos="0 -8 5" euler="1.011 0 0"/>
		<!-- arctan(5/8) = 0.559  -1.57 - 0.559 = -2.129 -->
		<camera name="camera_head_zoomin" class="nmf" mode="track" ipd="0.068" pos="3 -3 1" euler="1.57 0 0.72" fovy="30"/>
		<camera name="camera_front_zoomin" class="nmf" mode="track" ipd="0.068" pos="8 0 1" euler="1.57 0 1.57" fovy="15"/>
	</worldbody>
	<actuator>
	</actuator>
	<sensor>
  </sensor>
</mujoco>