<mujoco model="Animat">
	<compiler autolimits="true" boundmass="1e-06" boundinertia="1e-12" angle="radian" eulerseq="XYZ" convexhull="true" fusestatic="true" />
	<option timestep="0.0001" gravity="0 0 -9810" integrator="Euler" solver="Newton" iterations="1000" tolerance="1e-12" noslip_iterations="100" noslip_tolerance="1e-08" mpr_iterations="100">
		<flag multiccd="enable" energy="enable" />
		
	</option>
	<size njmax="4096" nconmax="4096" />
	<visual>
		<global offwidth="1280" offheight="720" />
		<quality shadowsize="1024" offsamples="4" numslices="28" numstacks="16" numquads="4" />
		<map stiffness="100.0" stiffnessrot="500.0" force="2.0" torque="1.0" alpha="0.3" fogstart="3.0" fogend="10.0" znear="0.0001" zfar="3.0" haze="0.3" shadowclip="1.0" shadowscale="0.3" actuatortendon="2.0" />
		<scale forcewidth="12.0" contactwidth="12.0" contactheight="50.0" connect="1.0" com="1.0" camera="1.0" light="1.0" selectpoint="1.0" jointlength="1.0" jointwidth="1.0" actuatorlength="1.0" actuatorwidth="1.0" framelength="0.01" framewidth="0.01" constraint="0.01" slidercrank="0.01" />
	</visual>
	<statistic meanmass="1.0" meaninertia="1.0" meansize="1.0" />
	<default>
		<default class="nmf" />
	</default>
	<asset>
		<mesh name="mesh_Thorax" class="nmf" file="../mesh/Thorax.stl" scale="1000 1000 1000" />
		<mesh name="mesh_A1A2" class="nmf" file="../mesh/A1A2.stl" scale="1000 1000 1000" />
		<mesh name="mesh_A3" class="nmf" file="../mesh/A3.stl" scale="1000 1000 1000" />
		<mesh name="mesh_A4" class="nmf" file="../mesh/A4.stl" scale="1000 1000 1000" />
		<mesh name="mesh_A5" class="nmf" file="../mesh/A5.stl" scale="1000 1000 1000" />
		<mesh name="mesh_A6" class="nmf" file="../mesh/A6.stl" scale="1000 1000 1000" />
		<mesh name="mesh_Head" class="nmf" file="../mesh/Head.stl" scale="1000 1000 1000" />
		<mesh name="mesh_REye" class="nmf" file="../mesh/REye.stl" scale="1000 1000 1000" />
		<mesh name="mesh_Rostrum" class="nmf" file="../mesh/Rostrum.stl" scale="1000 1000 1000" />
		<mesh name="mesh_Haustellum" class="nmf" file="../mesh/Haustellum.stl" scale="1000 1000 1000" />
		<mesh name="mesh_RPedicel" class="nmf" file="../mesh/RPedicel.stl" scale="1000 1000 1000" />
		<mesh name="mesh_RFuniculus" class="nmf" file="../mesh/RFuniculus.stl" scale="1000 1000 1000" />
		<mesh name="mesh_RArista" class="nmf" file="../mesh/RArista.stl" scale="1000 1000 1000" />
		<mesh name="mesh_RFCoxa" class="nmf" file="../mesh/RFCoxa.stl" scale="1000 1000 1000" />
		<mesh name="mesh_RFFemur" class="nmf" file="../mesh/RFFemur.stl" scale="1000 1000 1000" />
		<mesh name="mesh_RFTibia" class="nmf" file="../mesh/RFTibia.stl" scale="1000 1000 1000" />
		<mesh name="mesh_RFTarsus1" class="nmf" file="../mesh/RFTarsus1.stl" scale="1000 1000 1000" />
		<mesh name="mesh_RFTarsus2" class="nmf" file="../mesh/RFTarsus2.stl" scale="1000 1000 1000" />
		<mesh name="mesh_RFTarsus3" class="nmf" file="../mesh/RFTarsus3.stl" scale="1000 1000 1000" />
		<mesh name="mesh_RFTarsus4" class="nmf" file="../mesh/RFTarsus4.stl" scale="1000 1000 1000" />
		<mesh name="mesh_RFTarsus5" class="nmf" file="../mesh/RFTarsus5.stl" scale="1000 1000 1000" />
		<mesh name="mesh_RHaltere" class="nmf" file="../mesh/RHaltere.stl" scale="1000 1000 1000" />
		<mesh name="mesh_RHCoxa" class="nmf" file="../mesh/RHCoxa.stl" scale="1000 1000 1000" />
		<mesh name="mesh_RHFemur" class="nmf" file="../mesh/RHFemur.stl" scale="1000 1000 1000" />
		<mesh name="mesh_RHTibia" class="nmf" file="../mesh/RHTibia.stl" scale="1000 1000 1000" />
		<mesh name="mesh_RHTarsus1" class="nmf" file="../mesh/RHTarsus1.stl" scale="1000 1000 1000" />
		<mesh name="mesh_RHTarsus2" class="nmf" file="../mesh/RHTarsus2.stl" scale="1000 1000 1000" />
		<mesh name="mesh_RHTarsus3" class="nmf" file="../mesh/RHTarsus3.stl" scale="1000 1000 1000" />
		<mesh name="mesh_RHTarsus4" class="nmf" file="../mesh/RHTarsus4.stl" scale="1000 1000 1000" />
		<mesh name="mesh_RHTarsus5" class="nmf" file="../mesh/RHTarsus5.stl" scale="1000 1000 1000" />
		<mesh name="mesh_RMCoxa" class="nmf" file="../mesh/RMCoxa.stl" scale="1000 1000 1000" />
		<mesh name="mesh_RMFemur" class="nmf" file="../mesh/RMFemur.stl" scale="1000 1000 1000" />
		<mesh name="mesh_RMTibia" class="nmf" file="../mesh/RMTibia.stl" scale="1000 1000 1000" />
		<mesh name="mesh_RMTarsus1" class="nmf" file="../mesh/RMTarsus1.stl" scale="1000 1000 1000" />
		<mesh name="mesh_RMTarsus2" class="nmf" file="../mesh/RMTarsus2.stl" scale="1000 1000 1000" />
		<mesh name="mesh_RMTarsus3" class="nmf" file="../mesh/RMTarsus3.stl" scale="1000 1000 1000" />
		<mesh name="mesh_RMTarsus4" class="nmf" file="../mesh/RMTarsus4.stl" scale="1000 1000 1000" />
		<mesh name="mesh_RMTarsus5" class="nmf" file="../mesh/RMTarsus5.stl" scale="1000 1000 1000" />
		<mesh name="mesh_RWing" class="nmf" file="../mesh/RWing.stl" scale="1000 1000 1000" />
		<texture name="skybox" type="skybox" builtin="gradient" rgb1="1.0 1.0 1.0" rgb2="1.0 1.0 1.0" width="10" height="10" />
		<mesh name="mesh_LEye" class="nmf" file="../mesh/REye.stl" scale="1000 -1000 1000" />
		<mesh name="mesh_LPedicel" class="nmf" file="../mesh/RPedicel.stl" scale="1000 -1000 1000" />
		<mesh name="mesh_LFuniculus" class="nmf" file="../mesh/RFuniculus.stl" scale="1000 -1000 1000" />
		<mesh name="mesh_LArista" class="nmf" file="../mesh/RArista.stl" scale="1000 -1000 1000" />
		<mesh name="mesh_LFCoxa" class="nmf" file="../mesh/RFCoxa.stl" scale="1000 -1000 1000" />
		<mesh name="mesh_LFFemur" class="nmf" file="../mesh/RFFemur.stl" scale="1000 -1000 1000" />
		<mesh name="mesh_LFTibia" class="nmf" file="../mesh/RFTibia.stl" scale="1000 -1000 1000" />
		<mesh name="mesh_LFTarsus1" class="nmf" file="../mesh/RFTarsus1.stl" scale="1000 -1000 1000" />
		<mesh name="mesh_LFTarsus2" class="nmf" file="../mesh/RFTarsus2.stl" scale="1000 -1000 1000" />
		<mesh name="mesh_LFTarsus3" class="nmf" file="../mesh/RFTarsus3.stl" scale="1000 -1000 1000" />
		<mesh name="mesh_LFTarsus4" class="nmf" file="../mesh/RFTarsus4.stl" scale="1000 -1000 1000" />
		<mesh name="mesh_LFTarsus5" class="nmf" file="../mesh/RFTarsus5.stl" scale="1000 -1000 1000" />
		<mesh name="mesh_LHaltere" class="nmf" file="../mesh/RHaltere.stl" scale="1000 -1000 1000" />
		<mesh name="mesh_LHCoxa" class="nmf" file="../mesh/RHCoxa.stl" scale="1000 -1000 1000" />
		<mesh name="mesh_LHFemur" class="nmf" file="../mesh/RHFemur.stl" scale="1000 -1000 1000" />
		<mesh name="mesh_LHTibia" class="nmf" file="../mesh/RHTibia.stl" scale="1000 -1000 1000" />
		<mesh name="mesh_LHTarsus1" class="nmf" file="../mesh/RHTarsus1.stl" scale="1000 -1000 1000" />
		<mesh name="mesh_LHTarsus2" class="nmf" file="../mesh/RHTarsus2.stl" scale="1000 -1000 1000" />
		<mesh name="mesh_LHTarsus3" class="nmf" file="../mesh/RHTarsus3.stl" scale="1000 -1000 1000" />
		<mesh name="mesh_LHTarsus4" class="nmf" file="../mesh/RHTarsus4.stl" scale="1000 -1000 1000" />
		<mesh name="mesh_LHTarsus5" class="nmf" file="../mesh/RHTarsus5.stl" scale="1000 -1000 1000" />
		<mesh name="mesh_LMCoxa" class="nmf" file="../mesh/RMCoxa.stl" scale="1000 -1000 1000" />
		<mesh name="mesh_LMFemur" class="nmf" file="../mesh/RMFemur.stl" scale="1000 -1000 1000" />
		<mesh name="mesh_LMTibia" class="nmf" file="../mesh/RMTibia.stl" scale="1000 -1000 1000" />
		<mesh name="mesh_LMTarsus1" class="nmf" file="../mesh/RMTarsus1.stl" scale="1000 -1000 1000" />
		<mesh name="mesh_LMTarsus2" class="nmf" file="../mesh/RMTarsus2.stl" scale="1000 -1000 1000" />
		<mesh name="mesh_LMTarsus3" class="nmf" file="../mesh/RMTarsus3.stl" scale="1000 -1000 1000" />
		<mesh name="mesh_LMTarsus4" class="nmf" file="../mesh/RMTarsus4.stl" scale="1000 -1000 1000" />
		<mesh name="mesh_LMTarsus5" class="nmf" file="../mesh/RMTarsus5.stl" scale="1000 -1000 1000" />
		<mesh name="mesh_LWing" class="nmf" file="../mesh/RWing.stl" scale="1000 -1000 1000" />
	</asset>
	<worldbody>
		<body name="Thorax" pos="0.48076672828756273 -5.750451226305131e-07 1.2107710354030132" quat="1 0 0 0">
			<geom name="Thorax" class="nmf" type="mesh" contype="0" conaffinity="0" group="1" pos="0 0 0" quat="1 0 0 0" mesh="mesh_Thorax" mass="0.0003071677023684708" />
			<body name="A1A2" pos="-0.3096564032603055 -6.095955962237554e-07 0.9105792851187289" quat="0.991 0.0 -0.131  0.0">
				<geom name="A1A2" class="nmf" type="mesh" contype="0" conaffinity="0" group="1" pos="0 0 0" quat="1 0 0 0" mesh="mesh_A1A2" mass="8.5714247167182e-05" />
				<body name="A3" pos="-0.6661299848929048 -6.225838733442401e-07 0.9098725859075785" quat="0.999 0.0 -0.043 0.0">
					<geom name="A3" class="nmf" type="mesh" contype="0" conaffinity="0" condim="3" group="2" friction="1 0 0" solref="-1000000 -10000" margin="0.0" pos="0 0 0" quat="1 0 0 0" mesh="mesh_A3" fluidcoef="0 0 0 0 0" mass="0.00010703994712944607" />
					<body name="A4" pos="-0.9037149138748646 -6.236073324394908e-07 0.9102310286834836" quat="0.999 0.0 0.043 0.0">
						<geom name="A4" class="nmf" type="mesh" contype="0" conaffinity="0" condim="3" group="2" friction="1 0 0" solref="-1000000 -10000" margin="0.0" pos="0 0 0" quat="1 0 0 0" mesh="mesh_A4" fluidcoef="0 0 0 0 0" mass="9.75245118031497e-05" />
						<body name="A5" pos="-1.1180111905559897 -6.257803164544384e-07 0.9101369068957865" quat="1.0 0.0 0.009 0.0">
							<geom name="A5" class="nmf" type="mesh" contype="0" conaffinity="0" condim="3" group="2" friction="1 0 0" solref="-1000000 -10000" margin="0.0" pos="0 0 0" quat="1 0 0 0" mesh="mesh_A5" fluidcoef="0 0 0 0 0" mass="9.704502211966751e-05" />
							<body name="A6" pos="-1.386060263030231 -6.225402415793724e-07 0.9106406359933317" quat="1.0 0.0 0.009 0.0">
								<geom name="A6" class="nmf" type="mesh" contype="0" conaffinity="0" condim="3" group="2" friction="1 0 0" solref="-1000000 -10000" margin="0.0" pos="0 0 0" quat="1 0 0 0" mesh="mesh_A6" fluidcoef="0 0 0 0 0" mass="6.267627178055471e-05" />
							</body>
						</body>
					</body>
				</body>
			</body>
			<body name="LHaltere" pos="-0.2589677460491657 0.21355571516323835 0.9370104526169598" quat="1 0 0 0">
				<geom name="LHaltere" class="nmf" type="mesh" contype="0" conaffinity="0" group="1" pos="0 0 0" quat="1 0 0 0" mesh="mesh_LHaltere" mass="1.4161516439449333e-06" />
			</body>
			<body name="LWing" pos="-0.09160547779174522 0.3698323271237314 1.3241820270195603" quat="0.7071067657322373 0 0 0.70710679664085752">
				<geom name="LWing" class="nmf" type="mesh" contype="0" conaffinity="0" group="1" pos="0 0 0" quat="1 0 0 -1.4551916978336921e-15" mesh="mesh_LWing" mass="2.500060809494719e-06" />
			</body>
			<body name="RHaltere" pos="-0.2589676296338439 -0.21355725766625255 0.9370102197863162" quat="1 0 0 0">
				<geom name="RHaltere" class="nmf" type="mesh" contype="0" conaffinity="0" group="1" pos="0 0 0" quat="1 0 0 0" mesh="mesh_RHaltere" mass="1.4161459875842644e-06" />
			</body>
			<body name="RWing" pos="-0.09160557965515181 -0.36983360769227147 1.324181561358273" quat="0.7071067657322373 0 0 -0.70710679664085752">
				<geom name="RWing" class="nmf" type="mesh" contype="0" conaffinity="0" group="1" pos="0 0 0" quat="1 0 0 1.4551916978336921e-15" mesh="mesh_RWing" mass="2.499939190505281e-06" />
			</body>
			<body name="LFCoxa" pos="0.417999952333048 0.2699994365684688 1.0799976298585534" quat="1 0 0 0">
				<geom name="LFCoxa" class="nmf" type="mesh" contype="0" conaffinity="0" condim="3" group="2" friction="1 0 0" solref="-1000000 -10000" margin="0.0" pos="0 0 0" quat="1 0 0 0" mesh="mesh_LFCoxa" fluidcoef="0 0 0 0 0" mass="4.522004066249335e-06" />
				<joint name="joint_LFCoxa_yaw" class="nmf" type="hinge" pos="0 0 0" axis="1 0 0" stiffness="0.0" springref="0.0" damping="0.01" frictionloss="0.0" />
				<joint name="joint_LFCoxa" class="nmf" type="hinge" pos="0 0 0" axis="0 1 0" stiffness="0.0" springref="0.0" damping="0.01" frictionloss="0.0" />
				<joint name="joint_LFCoxa_roll" class="nmf" type="hinge" pos="0 0 0" axis="0 0 1" stiffness="0.0" springref="0.0" damping="0.1" frictionloss="0.0" />
				<body name="LFFemur" pos="0.417999952333048 0.2699994365684688 0.6545163923874497" quat="1 0 0 0">
					<geom name="LFFemur" class="nmf" type="mesh" contype="0" conaffinity="0" condim="3" group="2" friction="1 0 0" solref="-1000000 -10000" margin="0.0" pos="0 0 0" quat="1 0 0 0" mesh="mesh_LFFemur" fluidcoef="0 0 0 0 0" mass="6.294365178570592e-06" />
					<joint name="joint_LFFemur" class="nmf" type="hinge" pos="0 0 0" axis="0 1 0" stiffness="0.0" springref="0.0" damping="0.01" frictionloss="0.0" />
					<joint name="joint_LFFemur_roll" class="nmf" type="hinge" pos="0 0 0" axis="0 0 1" stiffness="0.0" springref="0.0" damping="0.01" frictionloss="0.0" />
					<body name="LFTibia" pos="0.417999952333048 0.2699994365684688 -0.050723549065878615" quat="1 0 0 0">
						<joint name="joint_LFTibia" class="nmf" type="hinge" pos="0 0 0" axis="0 1 0" stiffness="0.0" springref="0.0" damping="0.01" frictionloss="0.0" />
						<geom name="LFTibia" class="nmf" type="mesh" contype="0" conaffinity="0" condim="3" group="2" friction="2 0 0" solref="-1000000 -10000" margin="0.0" pos="0 0 0" quat="1 0 0 0" mesh="mesh_LFTibia" fluidcoef="0 0 0 0 0" mass="2.068820618721865e-06" />
						<body name="LFTarsus1" pos="0.417999952333048 0.2699994365684688 -0.569105613976717" quat="1 0 0 0">
							<joint name="joint_LFTarsus1" class="nmf" type="hinge" pos="0 0 0" axis="0 1 0" stiffness="0.0" springref="0.0" damping="0.1" frictionloss="0.0" />
							<geom name="LFTarsus1" class="nmf" type="mesh" contype="0" conaffinity="0" condim="3" group="2" friction="2 0 0" solref="-1000000 -10000" margin="0.0" pos="0 0 0" quat="1 0 0 0" mesh="mesh_LFTarsus1" fluidcoef="0 0 0 0 0" mass="4.64851133190333e-07" />
							<body name="LFTarsus2" pos="0.417999952333048 0.2699994365684688 -0.7946225232444704" quat="1 0 0 0">
								<joint name="joint_LFTarsus2" class="nmf" type="hinge" pos="0 0 0" axis="0 1 0" stiffness="0.0" springref="0.0" damping="0.1" frictionloss="0.0" />
								<geom name="LFTarsus2" class="nmf" type="mesh" contype="0" conaffinity="0" condim="3" group="2" friction="2 0 0" solref="-1000000 -10000" margin="0.0" pos="0 0 0" quat="1 0 0 0" mesh="mesh_LFTarsus2" fluidcoef="0 0 0 0 0" mass="2.0941328890791866e-07" />
								<body name="LFTarsus3" pos="0.417999952333048 0.2699994365684688 -0.9482912137173116" quat="1 0 0 0">
									<joint name="joint_LFTarsus3" class="nmf" type="hinge" pos="0 0 0" axis="0 1 0" stiffness="0.0" springref="0.0" damping="0.1" frictionloss="0.0" />
									<geom name="LFTarsus3" class="nmf" type="mesh" contype="0" conaffinity="0" condim="3" group="2" friction="2 0 0" solref="-1000000 -10000" margin="0.0" pos="0 0 0" quat="1 0 0 0" mesh="mesh_LFTarsus3" fluidcoef="0 0 0 0 0" mass="1.1851731000018943e-07" />
									<body name="LFTarsus4" pos="0.417999952333048 0.2699994365684688 -1.0467886459082365" quat="1 0 0 0">
										<joint name="joint_LFTarsus4" class="nmf" type="hinge" pos="0 0 0" axis="0 1 0" stiffness="0.0" springref="0.0" damping="0.1" frictionloss="0.0" />
										<geom name="LFTarsus4" class="nmf" type="mesh" contype="0" conaffinity="0" condim="3" group="2" friction="2 0 0" solref="-1000000 -10000" margin="0.0" pos="0 0 0" quat="1 0 0 0" mesh="mesh_LFTarsus4" fluidcoef="0 0 0 0 0" mass="9.269679574872209e-08" />
										<body name="LFTarsus5" pos="0.417999952333048 0.2699994365684688 -1.1337874457240105" quat="1 0 0 0">
											<joint name="joint_LFTarsus5" class="nmf" type="hinge" pos="0 0 0" axis="0 1 0" stiffness="0.0" springref="0.0" damping="0.1" frictionloss="0.0" />
											<geom name="LFTarsus5" class="nmf" type="mesh" contype="0" conaffinity="0" condim="3" group="2" friction="2 0 0" solref="-1000000 -10000" margin="0.0" pos="0 0 0" quat="1 0 0 0" mesh="mesh_LFTarsus5" fluidcoef="0 0 0 0 0" mass="1.1454791813432703e-07" />
										</body>
									</body>
								</body>
							</body>
						</body>
					</body>
				</body>
			</body>
			<body name="LHCoxa" pos="-0.14771765563637018 0.08699285535840318 0.6072233081795275" quat="1 0 0 0">
				<geom name="LHCoxa" class="nmf" type="mesh" contype="0" conaffinity="0" condim="3" group="2" friction="0 0 0" solref="-1000000 -10000" margin="0.0" pos="0 0 0" quat="1 0 0 0" mesh="mesh_LHCoxa" mass="2.5634613650929467e-06" />
				<joint name="joint_LHCoxa_yaw" class="nmf" type="hinge" pos="0 0 0" axis="1 0 0" stiffness="0.0" springref="0.0" damping="0.01" frictionloss="0.0" />
				<joint name="joint_LHCoxa" class="nmf" type="hinge" pos="0 0 0" axis="0 1 0" stiffness="0.0" springref="0.0" damping="0.01" frictionloss="0.0" />
				<joint name="joint_LHCoxa_roll" class="nmf" type="hinge" pos="0 0 0" axis="0 0 1" stiffness="0.0" springref="0.0" damping="0.01" frictionloss="0.0" />
				<body name="LHFemur" pos="-0.14799235214013606 0.08676703873788938 0.40780624840408564" quat="1 0 0 0">
					<geom name="LHFemur" class="nmf" type="mesh" contype="0" conaffinity="0" condim="3" group="2" friction="1 0 0" solref="-1000000 -10000" margin="0.0" pos="0 0 0" quat="1 0 0 0" mesh="mesh_LHFemur" fluidcoef="0 0 0 0 0" mass="8.752848223782955e-06" />
					<joint name="joint_LHFemur" class="nmf" type="hinge" pos="0 0 0" axis="0 1 0" stiffness="0.0" springref="0.0" damping="0.01" frictionloss="0.0" />
					<joint name="joint_LHFemur_roll" class="nmf" type="hinge" pos="0 0 0" axis="0 0 1" stiffness="0.0" springref="0.0" damping="0.01" frictionloss="0.0" />
					<body name="LHTibia" pos="-0.14785659732297063 0.08640384476166219 -0.42850757017731667" quat="1 0 0 0">
						<joint name="joint_LHTibia" class="nmf" type="hinge" pos="0 0 0" axis="0 1 0" stiffness="0.0" springref="0.0" damping="0.01" frictionloss="0.0" />
						<geom name="LHTibia" class="nmf" type="mesh" contype="0" conaffinity="0" condim="3" group="2" friction="1 0 0" solref="-1000000 -10000" margin="0.0" pos="0 0 0" quat="1 0 0 0" mesh="mesh_LHTibia" fluidcoef="0 0 0 0 0" mass="3.3711467153216586e-06" />
						<body name="LHTarsus1" pos="-0.14759648183826357 0.08577121479902416 -1.1129628401249647" quat="1 0 0 0">
							<joint name="joint_LHTarsus1" class="nmf" type="hinge" pos="0 0 0" axis="0 1 0" stiffness="0.0" springref="0.0" damping="0.1" frictionloss="0.0" />
							<geom name="LHTarsus1" class="nmf" type="mesh" contype="0" conaffinity="0" condim="3" group="2" friction="2 0 0" solref="-1000000 -10000" margin="0.0" pos="0 0 0" quat="1 0 0 0" mesh="mesh_LHTarsus1" fluidcoef="0 0 0 0 0" mass="1.0435290417843564e-06" />
							<body name="LHTarsus2" pos="-0.1476550241932273 0.08641673775855452 -1.4657053397968411" quat="1 0 0 0">
								<joint name="joint_LHTarsus2" class="nmf" type="hinge" pos="0 0 0" axis="0 1 0" stiffness="0.0" springref="0.0" damping="0.1" frictionloss="0.0" />
								<geom name="LHTarsus2" class="nmf" type="mesh" contype="0" conaffinity="0" condim="3" group="2" friction="2 0 0" solref="-1000000 -10000" margin="0.0" pos="0 0 0" quat="1 0 0 0" mesh="mesh_LHTarsus2" fluidcoef="0 0 0 0 0" mass="3.5169703880210384e-07" />
								<body name="LHTarsus3" pos="-0.14763572835363448 0.08545085438527167 -1.6407578950747848" quat="1 0 0 0">
									<joint name="joint_LHTarsus3" class="nmf" type="hinge" pos="0 0 0" axis="0 1 0" stiffness="0.0" springref="0.0" damping="0.1" frictionloss="0.0" />
									<geom name="LHTarsus3" class="nmf" type="mesh" contype="0" conaffinity="0" condim="3" group="2" friction="2 0 0" solref="-1000000 -10000" margin="0.0" pos="0 0 0" quat="1 0 0 0" mesh="mesh_LHTarsus3" fluidcoef="0 0 0 0 0" mass="1.3524270807158195e-07" />
									<body name="LHTarsus4" pos="-0.1476290781283751 0.08640861051389948 -1.7374661983922124" quat="1 0 0 0">
										<joint name="joint_LHTarsus4" class="nmf" type="hinge" pos="0 0 0" axis="0 1 0" stiffness="0.0" springref="0.0" damping="0.1" frictionloss="0.0" />
										<geom name="LHTarsus4" class="nmf" type="mesh" contype="0" conaffinity="0" condim="3" group="2" friction="2 0 0" solref="-1000000 -10000" margin="0.0" pos="0 0 0" quat="1 0 0 0" mesh="mesh_LHTarsus4" fluidcoef="0 0 0 0 0" mass="9.012496547607395e-08" />
										<body name="LHTarsus5" pos="-0.14755726442672312 0.08615519618615508 -1.8107704818248749" quat="1 0 0 0">
											<joint name="joint_LHTarsus5" class="nmf" type="hinge" pos="0 0 0" axis="0 1 0" stiffness="0.0" springref="0.0" damping="0.1" frictionloss="0.0" />
											<geom name="LHTarsus5" class="nmf" type="mesh" contype="0" conaffinity="0" condim="3" group="2" friction="2 0 0" solref="-1000000 -10000" margin="0.0" pos="0 0 0" quat="1 0 0 0" mesh="mesh_LHTarsus5" fluidcoef="0 0 0 0 0" mass="1.2468543442329055e-07" />
										</body>
									</body>
								</body>
							</body>
						</body>
					</body>
				</body>
			</body>
			<body name="LMCoxa" pos="0.06767547893105075 0.12490047083701938 0.6798476679250598" quat="1 0 0 0">
				<geom name="LMCoxa" class="nmf" type="mesh" contype="0" conaffinity="0" condim="3" group="2" friction="0 0 0" solref="-1000000 -10000" margin="0.0" pos="0 0 0" quat="1 0 0 0" mesh="mesh_LMCoxa" mass="2.5958093133598814e-06" />
				<joint name="joint_LMCoxa_yaw" class="nmf" type="hinge" pos="0 0 0" axis="1 0 0" stiffness="0.0" springref="0.0" damping="0.01" frictionloss="0.0" />
				<joint name="joint_LMCoxa" class="nmf" type="hinge" pos="0 0 0" axis="0 1 0" stiffness="0.0" springref="0.0" damping="0.01" frictionloss="0.0" />
				<joint name="joint_LMCoxa_roll" class="nmf" type="hinge" pos="0 0 0" axis="0 0 1" stiffness="0.0" springref="0.0" damping="0.01" frictionloss="0.0" />
				<body name="LMFemur" pos="0.067459637648426 0.12510624947026372 0.4984009428881109" quat="1 0 0 0">
					<geom name="LMFemur" class="nmf" type="mesh" contype="0" conaffinity="0" condim="3" group="2" friction="1 0 0" solref="-1000000 -10000" margin="0.0" pos="0 0 0" quat="1 0 0 0" mesh="mesh_LMFemur" fluidcoef="0 0 0 0 0" mass="6.482330598202185e-06" />
					<joint name="joint_LMFemur" class="nmf" type="hinge" pos="0 0 0" axis="0 1 0" stiffness="0.0" springref="0.0" damping="0.01" frictionloss="0.0" />
					<joint name="joint_LMFemur_roll" class="nmf" type="hinge" pos="0 0 0" axis="0 0 1" stiffness="0.0" springref="0.0" damping="0.01" frictionloss="0.0" />
					<body name="LMTibia" pos="0.06649007991654798 0.1256917603313923 -0.2852689940482378" quat="1 0 0 0">
						<joint name="joint_LMTibia" class="nmf" type="hinge" pos="0 0 0" axis="0 1 0" stiffness="0.0" springref="0.0" damping="0.01" frictionloss="0.0" />
						<geom name="LMTibia" class="nmf" type="mesh" contype="0" conaffinity="0" condim="3" group="2" friction="1 0 0" solref="-1000000 -10000" margin="0.0" pos="0 0 0" quat="1 0 0 0" mesh="mesh_LMTibia" fluidcoef="0 0 0 0 0" mass="2.8600945241498507e-06" />
						<body name="LMTarsus1" pos="0.06676963676000014 0.1262413861695677 -0.9525956702418625" quat="1 0 0 0">
							<joint name="joint_LMTarsus1" class="nmf" type="hinge" pos="0 0 0" axis="0 1 0" stiffness="0.0" springref="0.0" damping="0.1" frictionloss="0.0" />
							<geom name="LMTarsus1" class="nmf" type="mesh" contype="0" conaffinity="0" condim="3" group="2" friction="2 0 0" solref="-1000000 -10000" margin="0.0" pos="0 0 0" quat="1 0 0 0" mesh="mesh_LMTarsus1" fluidcoef="0 0 0 0 0" mass="5.247556124991491e-07" />
							<body name="LMTarsus2" pos="0.0672164314892143 0.12576088192872703 -1.2469320790842175" quat="1 0 0 0">
								<joint name="joint_LMTarsus2" class="nmf" type="hinge" pos="0 0 0" axis="0 1 0" stiffness="0.0" springref="0.0" damping="0.1" frictionloss="0.0" />
								<geom name="LMTarsus2" class="nmf" type="mesh" contype="0" conaffinity="0" condim="3" group="2" friction="2 0 0" solref="-1000000 -10000" margin="0.0" pos="0 0 0" quat="1 0 0 0" mesh="mesh_LMTarsus2" fluidcoef="0 0 0 0 0" mass="2.354010887465768e-07" />
								<body name="LMTarsus3" pos="0.06712540198350325 0.12566363147925586 -1.4060972025617957" quat="1 0 0 0">
									<joint name="joint_LMTarsus3" class="nmf" type="hinge" pos="0 0 0" axis="0 1 0" stiffness="0.0" springref="0.0" damping="0.1" frictionloss="0.0" />
									<geom name="LMTarsus3" class="nmf" type="mesh" contype="0" conaffinity="0" condim="3" group="2" friction="2 0 0" solref="-1000000 -10000" margin="0.0" pos="0 0 0" quat="1 0 0 0" mesh="mesh_LMTarsus3" fluidcoef="0 0 0 0 0" mass="1.176311900856616e-07" />
									<body name="LMTarsus4" pos="0.06735506758559495 0.12555441935546696 -1.495831529609859" quat="1 0 0 0">
										<joint name="joint_LMTarsus4" class="nmf" type="hinge" pos="0 0 0" axis="0 1 0" stiffness="0.0" springref="0.0" damping="0.1" frictionloss="0.0" />
										<geom name="LMTarsus4" class="nmf" type="mesh" contype="0" conaffinity="0" condim="3" group="2" friction="2 0 0" solref="-1000000 -10000" margin="0.0" pos="0 0 0" quat="1 0 0 0" mesh="mesh_LMTarsus4" fluidcoef="0 0 0 0 0" mass="6.844311672551234e-08" />
										<body name="LMTarsus5" pos="0.06754857167834416 0.12564996723085642 -1.559109310619533" quat="1 0 0 0">
											<joint name="joint_LMTarsus5" class="nmf" type="hinge" pos="0 0 0" axis="0 1 0" stiffness="0.0" springref="0.0" damping="0.1" frictionloss="0.0" />
											<geom name="LMTarsus5" class="nmf" type="mesh" contype="0" conaffinity="0" condim="3" group="2" friction="2 0 0" solref="-1000000 -10000" margin="0.0" pos="0 0 0" quat="1 0 0 0" mesh="mesh_LMTarsus5" fluidcoef="0 0 0 0 0" mass="1.1399435799447945e-07" />
										</body>
									</body>
								</body>
							</body>
						</body>
					</body>
				</body>
			</body>
			<body name="RHCoxa" pos="-0.14771783025935292 -0.08699407044332474 0.6072231335565448" quat="1 0 0 0">
				<geom name="RHCoxa" class="nmf" type="mesh" contype="0" conaffinity="0" condim="3" group="2" friction="0 0 0" solref="-1000000 -10000" margin="0.0" pos="0 0 0" quat="1 0 0 0" mesh="mesh_RHCoxa" mass="2.56346618880083e-06" />
				<joint name="joint_RHCoxa_yaw" class="nmf" type="hinge" pos="0 0 0" axis="1 0 0" stiffness="0.0" springref="0.0" damping="0.01" frictionloss="0.0" />
				<joint name="joint_RHCoxa" class="nmf" type="hinge" pos="0 0 0" axis="0 1 0" stiffness="0.0" springref="0.0" damping="0.01" frictionloss="0.0" />
				<joint name="joint_RHCoxa_roll" class="nmf" type="hinge" pos="0 0 0" axis="0 0 1" stiffness="0.0" springref="0.0" damping="0.01" frictionloss="0.0" />
				<body name="RHFemur" pos="-0.14779606135562062 -0.08657687430968508 0.40780630661174655" quat="1 0 0 0">
					<geom name="RHFemur" class="nmf" type="mesh" contype="0" conaffinity="0" condim="3" group="2" friction="1 0 0" solref="-1000000 -10000" margin="0.0" pos="0 0 0" quat="1 0 0 0" mesh="mesh_RHFemur" fluidcoef="0 0 0 0 0" mass="8.752846411343817e-06" />
					<joint name="joint_RHFemur" class="nmf" type="hinge" pos="0 0 0" axis="0 1 0" stiffness="0.0" springref="0.0" damping="0.01" frictionloss="0.0" />
					<joint name="joint_RHFemur_roll" class="nmf" type="hinge" pos="0 0 0" axis="0 0 1" stiffness="0.0" springref="0.0" damping="0.01" frictionloss="0.0" />
					<body name="RHTibia" pos="-0.14771343558095396 -0.08673848788021132 -0.42850716272369027" quat="1 0 0 0">
						<joint name="joint_RHTibia" class="nmf" type="hinge" pos="0 0 0" axis="0 1 0" stiffness="0.0" springref="0.0" damping="0.01" frictionloss="0.0" />
						<geom name="RHTibia" class="nmf" type="mesh" contype="0" conaffinity="0" condim="3" group="2" friction="1 0 0" solref="-1000000 -10000" margin="0.0" pos="0 0 0" quat="1 0 0 0" mesh="mesh_RHTibia" fluidcoef="0 0 0 0 0" mass="3.3711512886318823e-06" />
						<body name="RHTarsus1" pos="-0.14797464245930314 -0.08607671043137088 -1.1129623744636774" quat="1 0 0 0">
							<joint name="joint_RHTarsus1" class="nmf" type="hinge" pos="0 0 0" axis="0 1 0" stiffness="0.0" springref="0.0" damping="0.1" frictionloss="0.0" />
							<geom name="RHTarsus1" class="nmf" type="mesh" contype="0" conaffinity="0" condim="3" group="2" friction="2 0 0" solref="-1000000 -10000" margin="0.0" pos="0 0 0" quat="1 0 0 0" mesh="mesh_RHTarsus1" fluidcoef="0 0 0 0 0" mass="1.0435376475255117e-06" />
							<body name="RHTarsus2" pos="-0.1477215701015666 -0.08611853263573721 -1.465705456212163" quat="1 0 0 0">
								<joint name="joint_RHTarsus2" class="nmf" type="hinge" pos="0 0 0" axis="0 1 0" stiffness="0.0" springref="0.0" damping="0.1" frictionloss="0.0" />
								<geom name="RHTarsus2" class="nmf" type="mesh" contype="0" conaffinity="0" condim="3" group="2" friction="2 0 0" solref="-1000000 -10000" margin="0.0" pos="0 0 0" quat="1 0 0 0" mesh="mesh_RHTarsus2" fluidcoef="0 0 0 0 0" mass="3.516964968856457e-07" />
								<body name="RHTarsus3" pos="-0.14749380352441221 -0.08640878513688222 -1.6407601069658995" quat="1 0 0 0">
									<joint name="joint_RHTarsus3" class="nmf" type="hinge" pos="0 0 0" axis="0 1 0" stiffness="0.0" springref="0.0" damping="0.1" frictionloss="0.0" />
									<geom name="RHTarsus3" class="nmf" type="mesh" contype="0" conaffinity="0" condim="3" group="2" friction="2 0 0" solref="-1000000 -10000" margin="0.0" pos="0 0 0" quat="1 0 0 0" mesh="mesh_RHTarsus3" fluidcoef="0 0 0 0 0" mass="1.352428932360253e-07" />
									<body name="RHTarsus4" pos="-0.1480112550780177 -0.08602128946222365 -1.7374708550050855" quat="1 0 0 0">
										<joint name="joint_RHTarsus4" class="nmf" type="hinge" pos="0 0 0" axis="0 1 0" stiffness="0.0" springref="0.0" damping="0.1" frictionloss="0.0" />
										<geom name="RHTarsus4" class="nmf" type="mesh" contype="0" conaffinity="0" condim="3" group="2" friction="2 0 0" solref="-1000000 -10000" margin="0.0" pos="0 0 0" quat="1 0 0 0" mesh="mesh_RHTarsus4" fluidcoef="0 0 0 0 0" mass="9.01249567179059e-08" />
										<body name="RHTarsus5" pos="-0.14765464584343135 -0.08632257959106937 -1.8107742071151733" quat="1 0 0 0">
											<joint name="joint_RHTarsus5" class="nmf" type="hinge" pos="0 0 0" axis="0 1 0" stiffness="0.0" springref="0.0" damping="0.1" frictionloss="0.0" />
											<geom name="RHTarsus5" class="nmf" type="mesh" contype="0" conaffinity="0" condim="3" group="2" friction="2 0 0" solref="-1000000 -10000" margin="0.0" pos="0 0 0" quat="1 0 0 0" mesh="mesh_RHTarsus5" fluidcoef="0 0 0 0 0" mass="1.2468550520191837e-07" />
										</body>
									</body>
								</body>
							</body>
						</body>
					</body>
				</body>
			</body>
			<body name="RMCoxa" pos="0.06800005940021947 -0.12490185326896608 0.6798479007557034" quat="1 0 0 0">
				<geom name="RMCoxa" class="nmf" type="mesh" contype="0" conaffinity="0" condim="3" group="2" friction="0 0 0" solref="-1000000 -10000" margin="0.0" pos="0 0 0" quat="1 0 0 0" mesh="mesh_RMCoxa" mass="2.5958084153147036e-06" />
				<joint name="joint_RMCoxa_yaw" class="nmf" type="hinge" pos="0 0 0" axis="1 0 0" stiffness="0.0" springref="0.0" damping="0.01" frictionloss="0.0" />
				<joint name="joint_RMCoxa" class="nmf" type="hinge" pos="0 0 0" axis="0 1 0" stiffness="0.0" springref="0.0" damping="0.01" frictionloss="0.0" />
				<joint name="joint_RMCoxa_roll" class="nmf" type="hinge" pos="0 0 0" axis="0 0 1" stiffness="0.0" springref="0.0" damping="0.01" frictionloss="0.0" />
				<body name="RMFemur" pos="0.0674601542414166 -0.12511780369095504 0.49840123392641544" quat="1 0 0 0">
					<geom name="RMFemur" class="nmf" type="mesh" contype="0" conaffinity="0" condim="3" group="2" friction="1 0 0" solref="-1000000 -10000" margin="0.0" pos="0 0 0" quat="1 0 0 0" mesh="mesh_RMFemur" fluidcoef="0 0 0 0 0" mass="6.482327249565799e-06" />
					<joint name="joint_RMFemur" class="nmf" type="hinge" pos="0 0 0" axis="0 1 0" stiffness="0.0" springref="0.0" damping="0.01" frictionloss="0.0" />
					<joint name="joint_RMFemur_roll" class="nmf" type="hinge" pos="0 0 0" axis="0 0 1" stiffness="0.0" springref="0.0" damping="0.01" frictionloss="0.0" />
					<body name="RMTibia" pos="0.06648874114034697 -0.12517570576164871 -0.2852685865946114" quat="1 0 0 0">
						<joint name="joint_RMTibia" class="nmf" type="hinge" pos="0 0 0" axis="0 1 0" stiffness="0.0" springref="0.0" damping="0.01" frictionloss="0.0" />
						<geom name="RMTibia" class="nmf" type="mesh" contype="0" conaffinity="0" condim="3" group="2" friction="1 0 0" solref="-1000000 -10000" margin="0.0" pos="0 0 0" quat="1 0 0 0" mesh="mesh_RMTibia" fluidcoef="0 0 0 0 0" mass="2.8600997544055163e-06" />
						<body name="RMTarsus1" pos="0.06634154851781204 -0.12434118252713233 -0.9525948553346097" quat="1 0 0 0">
							<joint name="joint_RMTarsus1" class="nmf" type="hinge" pos="0 0 0" axis="0 1 0" stiffness="0.0" springref="0.0" damping="0.1" frictionloss="0.0" />
							<geom name="RMTarsus1" class="nmf" type="mesh" contype="0" conaffinity="0" condim="3" group="2" friction="0 0 0" solref="-1000000 -10000" margin="0.0" pos="0 0 0" quat="1 0 0 0" mesh="mesh_RMTarsus1" mass="5.24756450411376e-07" />
							<body name="RMTarsus2" pos="0.06691994349239394 -0.12482472811825573 -1.2425635941326618" quat="1 0 0 0">
								<joint name="joint_RMTarsus2" class="nmf" type="hinge" pos="0 0 0" axis="0 1 0" stiffness="0.0" springref="0.0" damping="0.1" frictionloss="0.0" />
								<geom name="RMTarsus2" class="nmf" type="mesh" contype="0" conaffinity="0" condim="3" group="2" friction="0 0 0" solref="-1000000 -10000" margin="0.0" pos="0 0 0" quat="1 0 0 0" mesh="mesh_RMTarsus2" mass="2.354013998600498e-07" />
								<body name="RMTarsus3" pos="0.06695505726383999 -0.12472497473936528 -1.402715570293367" quat="1 0 0 0">
									<joint name="joint_RMTarsus3" class="nmf" type="hinge" pos="0 0 0" axis="0 1 0" stiffness="0.0" springref="0.0" damping="0.1" frictionloss="0.0" />
									<geom name="RMTarsus3" class="nmf" type="mesh" contype="0" conaffinity="0" condim="3" group="2" friction="0 0 0" solref="-1000000 -10000" margin="0.0" pos="0 0 0" quat="1 0 0 0" mesh="mesh_RMTarsus3" mass="1.1763144858436786e-07" />
									<body name="RMTarsus4" pos="0.06647266127401963 -0.12451442307792604 -1.4951506163924932" quat="1 0 0 0">
										<joint name="joint_RMTarsus4" class="nmf" type="hinge" pos="0 0 0" axis="0 1 0" stiffness="0.0" springref="0.0" damping="0.1" frictionloss="0.0" />
										<geom name="RMTarsus4" class="nmf" type="mesh" contype="0" conaffinity="0" condim="3" group="2" friction="0 0 0" solref="-1000000 -10000" margin="0.0" pos="0 0 0" quat="1 0 0 0" mesh="mesh_RMTarsus4" mass="6.84432308676254e-08" />
										<body name="RMTarsus5" pos="0.0680825614836067 -0.12465985491871834 -1.5588728711009026" quat="1 0 0 0">
											<joint name="joint_RMTarsus5" class="nmf" type="hinge" pos="0 0 0" axis="0 1 0" stiffness="0.0" springref="0.0" damping="0.1" frictionloss="0.0" />
											<geom name="RMTarsus5" class="nmf" type="mesh" contype="0" conaffinity="0" condim="3" group="2" friction="0 0 0" solref="-1000000 -10000" margin="0.0" pos="0 0 0" quat="1 0 0 0" mesh="mesh_RMTarsus5" mass="1.1399464253693984e-07" />
										</body>
									</body>
								</body>
							</body>
						</body>
					</body>
				</body>
			</body>
			<body name="RFCoxa" pos="0.41799998143687844 -0.2700005716178566 1.0799976298585534" quat="1 0 0 0">
				<geom name="RFCoxa" class="nmf" type="mesh" contype="0" conaffinity="0" condim="3" group="2" friction="1 0 0" solref="-1000000 -10000" margin="0.0" pos="0 0 0" quat="1 0 0 0" mesh="mesh_RFCoxa" fluidcoef="0 0 0 0 0" mass="4.522002437988243e-06" />
				<joint name="joint_RFCoxa_yaw" class="nmf" type="hinge" pos="0 0 0" axis="1 0 0" stiffness="0.0" springref="0.0" damping="0.01" frictionloss="0.0" />
				<joint name="joint_RFCoxa" class="nmf" type="hinge" pos="0 0 0" axis="0 1 0" stiffness="0.0" springref="0.0" damping="0.01" frictionloss="0.0" />
				<joint name="joint_RFCoxa_roll" class="nmf" type="hinge" pos="0 0 0" axis="0 0 1" stiffness="0.0" springref="0.0" damping="0.01" frictionloss="0.0" />
				<body name="RFFemur" pos="0.41799998143687844 -0.2700005716178566 0.6545186042785645" quat="1 0 0 0">
					<geom name="RFFemur" class="nmf" type="mesh" contype="0" conaffinity="0" condim="3" group="2" friction="1 0 0" solref="-1000000 -10000" margin="0.0" pos="0 0 0" quat="1 0 0 0" mesh="mesh_RFFemur" fluidcoef="0 0 0 0 0" mass="6.294376034121718e-06" />
					<joint name="joint_RFFemur" class="nmf" type="hinge" pos="0 0 0" axis="0 1 0" stiffness="0.0" springref="0.0" damping="0.01" frictionloss="0.0" />
					<joint name="joint_RFFemur_roll" class="nmf" type="hinge" pos="0 0 0" axis="0 0 1" stiffness="0.0" springref="0.0" damping="0.01" frictionloss="0.0" />
					<body name="RFTibia" pos="0.41799998143687844 -0.2700005716178566 -0.0507213371747639" quat="1 0 0 0">
						<joint name="joint_RFTibia" class="nmf" type="hinge" pos="0 0 0" axis="0 1 0" stiffness="0.0" springref="0.0" damping="0.01" frictionloss="0.0" />
						<geom name="RFTibia" class="nmf" type="mesh" contype="0" conaffinity="0" condim="3" group="2" friction="2 0 0" solref="-1000000 -10000" margin="0.0" pos="0 0 0" quat="1 0 0 0" mesh="mesh_RFTibia" fluidcoef="0 0 0 0 0" mass="2.0688194360187594e-06" />
						<body name="RFTarsus1" pos="0.41799998143687844 -0.2700005716178566 -0.5691341357305646" quat="1 0 0 0">
							<camera name="camera_RFTarsus1_zoomin" class="nmf" mode="track" ipd="0.068" pos="-0.5 -2 0" euler="1.67 0 -0.3" fovy="60" />
							
							<joint name="joint_RFTarsus1" class="nmf" type="hinge" pos="0 0 0" axis="0 1 0" stiffness="0.0" springref="0.0" damping="0.1" frictionloss="0.0" />
							<geom name="RFTarsus1" class="nmf" type="mesh" contype="0" conaffinity="0" condim="3" group="2" friction="2 0 0" solref="-1000000 -10000" margin="0.0" pos="0 0 0" quat="1 0 0 0" mesh="mesh_RFTarsus1" fluidcoef="0 0 0 0 0" mass="4.6485138504422505e-07" />
							<body name="RFTarsus2" pos="0.41799998143687844 -0.2700005716178566 -0.7945623947307467" quat="1 0 0 0">
								<joint name="joint_RFTarsus2" class="nmf" type="hinge" pos="0 0 0" axis="0 1 0" stiffness="0.0" springref="0.0" damping="0.1" frictionloss="0.0" />
								<geom name="RFTarsus2" class="nmf" type="mesh" contype="0" conaffinity="0" condim="3" group="2" friction="2 0 0" solref="-1000000 -10000" margin="0.0" pos="0 0 0" quat="1 0 0 0" mesh="mesh_RFTarsus2" fluidcoef="0 0 0 0 0" mass="2.0941347570628474e-07" />
								<body name="RFTarsus3" pos="0.41799998143687844 -0.2700005716178566 -0.9482387104071677" quat="1 0 0 0">
									<joint name="joint_RFTarsus3" class="nmf" type="hinge" pos="0 0 0" axis="0 1 0" stiffness="0.0" springref="0.0" damping="0.1" frictionloss="0.0" />
									<geom name="RFTarsus3" class="nmf" type="mesh" contype="0" conaffinity="0" condim="3" group="2" friction="2 0 0" solref="-1000000 -10000" margin="0.0" pos="0 0 0" quat="1 0 0 0" mesh="mesh_RFTarsus3" fluidcoef="0 0 0 0 0" mass="1.1851737405370073e-07" />
									<body name="RFTarsus4" pos="0.41799998143687844 -0.2700005716178566 -1.0467406827956438" quat="1 0 0 0">
										<joint name="joint_RFTarsus4" class="nmf" type="hinge" pos="0 0 0" axis="0 1 0" stiffness="0.0" springref="0.0" damping="0.1" frictionloss="0.0" />
										<geom name="RFTarsus4" class="nmf" type="mesh" contype="0" conaffinity="0" condim="3" group="2" friction="2 0 0" solref="-1000000 -10000" margin="0.0" pos="0 0 0" quat="1 0 0 0" mesh="mesh_RFTarsus4" fluidcoef="0 0 0 0 0" mass="9.269690720771255e-08" />
										<body name="RFTarsus5" pos="0.41799998143687844 -0.2700005716178566 -1.1337626492604613" quat="1 0 0 0">
											<joint name="joint_RFTarsus5" class="nmf" type="hinge" pos="0 0 0" axis="0 1 0" stiffness="0.0" springref="0.0" damping="0.1" frictionloss="0.0" />
											<geom name="RFTarsus5" class="nmf" type="mesh" contype="0" conaffinity="0" condim="3" group="2" friction="2 0 0" solref="-1000000 -10000" margin="0.0" pos="0 0 0" quat="1 0 0 0" mesh="mesh_RFTarsus5" fluidcoef="0 0 0 0 0" mass="1.1454814826407663e-07" />
										</body>
									</body>
								</body>
							</body>
						</body>
					</body>
				</body>
			</body>
			<body name="Head" pos="0.49792276695370674 -6.537502761361225e-07 1.210771151818335" quat="1 0 0 0">
				<geom name="Head" class="nmf" type="mesh" contype="0" conaffinity="0" condim="3" group="2" friction="0 0 0" solref="-1000000 -10000" margin="0.0" pos="0 0 0" quat="1 0 0 0" mesh="mesh_Head" mass="9.455094693981879e-05" />
				<joint name="joint_Head_yaw" class="nmf" type="hinge" pos="0 0 0" axis="1 0 0" stiffness="0.0" springref="0.0" damping="0.2" frictionloss="0.0" />
				<joint name="joint_Head" class="nmf" type="hinge" pos="0 0 0" axis="0 1 0" stiffness="0.0" springref="0.0" damping="0.2" frictionloss="0.0" />
				<joint name="joint_Head_roll" class="nmf" type="hinge" pos="0 0 0" axis="0 0 1" stiffness="0.0" springref="0.0" damping="0.2" frictionloss="0.0" />
				<body name="LEye" pos="0.7299907738342881 -5.636520139518097e-07 1.2999811442568898" quat="1 0 0 0">
					<geom name="LEye" class="nmf" type="mesh" contype="0" conaffinity="0" condim="3" group="2" friction="0 0 0" solref="-1000000 -10000" margin="0.0" pos="0 0 0" quat="1 0 0 0" mesh="mesh_LEye" mass="1.251350088756361e-05" />
				</body>
				<body name="REye" pos="0.729990832041949 -5.634853139646623e-07 1.299981027841568" quat="1 0 0 0">
					<geom name="REye" class="nmf" type="mesh" contype="0" conaffinity="0" condim="3" group="2" friction="0 0 0" solref="-1000000 -10000" margin="0.0" pos="0 0 0" quat="1 0 0 0" mesh="mesh_REye" mass="1.0853648330100224e-05" />
				</body>
				<body name="Rostrum" pos="0.9129836107604206 0.000679564209349337 0.9984660428017378" quat="1 0 0 0">
					<geom name="Rostrum" class="nmf" type="mesh" contype="0" conaffinity="0" condim="3" group="2" friction="0 0 0" solref="-1000000 -10000" margin="0.0" pos="0 0 0" quat="1 0 0 0" mesh="mesh_Rostrum" mass="1.821516305100949e-05" />
					<body name="Haustellum" pos="0.9131766273640096 0.00023461312537165213 0.6270145531743765" quat="1 0 0 0">
						<geom name="Haustellum" class="nmf" type="mesh" contype="0" conaffinity="0" condim="3" group="2" friction="0 0 0" solref="-1000000 -10000" margin="0.0" pos="0 0 0" quat="1 0 0 0" mesh="mesh_Haustellum" mass="8.088172523948103e-06" />
					</body>
				</body>
				<body name="LPedicel" pos="0.428972452878952 0.0862061195075512 0.08255249261856079" quat="1 0 0 0">
					<geom name="LPedicel" class="nmf" type="mesh" contype="0" conaffinity="0" condim="3" group="2" friction="1 0 0" solref="-1000000 -10000" margin="0.0" pos="0 0 0" quat="1 0 0 0" mesh="mesh_LPedicel" fluidcoef="0 0 0 0 0" mass="8.662544835547314e-07" />
					<joint name="joint_LPedicel_yaw" class="nmf" type="hinge" pos="0 0 0" axis="1 0 0" stiffness="0.0" springref="0.0" damping="0.0001" frictionloss="0.0" />
					<joint name="joint_LPedicel" class="nmf" type="hinge" pos="0 0 0" axis="0 1 0" stiffness="0.0" springref="0.0" damping="0.0001" frictionloss="0.0" />
					<joint name="joint_LPedicel_roll" class="nmf" type="hinge" pos="0 0 0" axis="0 0 1" stiffness="0.0" springref="0.0" damping="0.0001" frictionloss="0.0" />
					<body name="LFuniculus" pos="0.051001936197280884 -0.000562518835067749 -0.044100403785705566" quat="1 0 0 0">
						<geom name="LFuniculus" class="nmf" type="mesh" contype="0" conaffinity="0" condim="3" group="2" friction="1 0 0" solref="-1000000 -10000" margin="0.0" pos="0 0 0" quat="1 0 0 0" mesh="mesh_LFuniculus" fluidcoef="0 0 0 0 0" mass="1.1002208214785619e-06" />
						<joint name="joint_LFuniculus_yaw" class="nmf" type="hinge" pos="0 0 0" axis="1 0 0" stiffness="0.0" springref="0.0" damping="0.0001" frictionloss="0.0" />
						<joint name="joint_LFuniculus" class="nmf" type="hinge" pos="0 0 0" axis="0 1 0" stiffness="0.0" springref="0.0" damping="0.0001" frictionloss="0.0" />
						<joint name="joint_LFuniculus_roll" class="nmf" type="hinge" pos="0 0 0" axis="0 0 1" stiffness="0.0" springref="0.0" damping="0.0001" frictionloss="0.0" />
						<body name="LArista" pos="0.01984727382659912 0.05385337397456169 -0.06828278303146362" quat="1 0 0 0">
							<geom name="LArista" class="nmf" type="mesh" contype="0" conaffinity="0" condim="3" group="2" friction="0.29999999999999999 0 0" solref="-1000000 -10000" margin="0.0" pos="0 0 0" quat="1 0 0 0" mesh="mesh_LArista" fluidcoef="0 0 0 0 0" mass="1.1001493090684334e-07" />
							<joint name="joint_LArista_yaw" class="nmf" type="hinge" pos="0 0 0" axis="1 0 0" stiffness="0.0" springref="0.0" damping="1e-05" frictionloss="0.0" />
							<joint name="joint_LArista" class="nmf" type="hinge" pos="0 0 0" axis="0 1 0" stiffness="0.0" springref="0.0" damping="1e-05" frictionloss="0.0" />
							<joint name="joint_LArista_roll" class="nmf" type="hinge" pos="0 0 0" axis="0 0 1" stiffness="0.0" springref="0.0" damping="1e-05" frictionloss="0.0" />
						</body>
					</body>
				</body>
				<body name="RPedicel" pos="0.428972452878952 -0.0862061195075512 0.08255249261856079" quat="1 0 0 0">
					<geom name="RPedicel" class="nmf" type="mesh" contype="0" conaffinity="0" condim="3" group="2" friction="1 0 0" solref="-1000000 -10000" margin="0.0" pos="0 0 0" quat="1 0 0 0" mesh="mesh_RPedicel" fluidcoef="0 0 0 0 0" mass="8.621888354241637e-07" />
					<joint name="joint_RPedicel_yaw" class="nmf" type="hinge" pos="0 0 0" axis="1 0 0" stiffness="0.0" springref="0.0" damping="0.0001" frictionloss="0.0" />
					<joint name="joint_RPedicel" class="nmf" type="hinge" pos="0 0 0" axis="0 1 0" stiffness="0.0" springref="0.0" damping="0.0001" frictionloss="0.0" />
					<joint name="joint_RPedicel_roll" class="nmf" type="hinge" pos="0 0 0" axis="0 0 1" stiffness="0.0" springref="0.0" damping="0.0001" frictionloss="0.0" />
					<body name="RFuniculus" pos="0.051001936197280884 0.000562518835067749 -0.044100403785705566" quat="1 0 0 0">
						<geom name="RFuniculus" class="nmf" type="mesh" contype="0" conaffinity="0" condim="3" group="2" friction="1 0 0" solref="-1000000 -10000" margin="0.0" pos="0 0 0" quat="1 0 0 0" mesh="mesh_RFuniculus" fluidcoef="0 0 0 0 0" mass="1.0970476498469152e-06" />
						<joint name="joint_RFuniculus_yaw" class="nmf" type="hinge" pos="0 0 0" axis="1 0 0" stiffness="0.0" springref="0.0" damping="0.0001" frictionloss="0.0" />
						<joint name="joint_RFuniculus" class="nmf" type="hinge" pos="0 0 0" axis="0 1 0" stiffness="0.0" springref="0.0" damping="0.0001" frictionloss="0.0" />
						<joint name="joint_RFuniculus_roll" class="nmf" type="hinge" pos="0 0 0" axis="0 0 1" stiffness="0.0" springref="0.0" damping="0.0001" frictionloss="0.0" />
						<body name="RArista" pos="0.01984727382659912 -0.05385337397456169 -0.06828278303146362" quat="1 0 0 0">
							<geom name="RArista" class="nmf" type="mesh" contype="0" conaffinity="0" condim="3" group="2" friction="0.29999999999999999 0 0" solref="-1000000 -10000" margin="0.0" pos="0 0 0" quat="1 0 0 0" mesh="mesh_RArista" fluidcoef="0 0 0 0 0" mass="1.099907640123722e-07" />
							<joint name="joint_RArista_yaw" class="nmf" type="hinge" pos="0 0 0" axis="1 0 0" stiffness="0.0" springref="0.0" damping="1e-05" frictionloss="0.0" />
							<joint name="joint_RArista" class="nmf" type="hinge" pos="0 0 0" axis="0 1 0" stiffness="0.0" springref="0.0" damping="1e-05" frictionloss="0.0" />
							<joint name="joint_RArista_roll" class="nmf" type="hinge" pos="0 0 0" axis="0 0 1" stiffness="0.0" springref="0.0" damping="1e-05" frictionloss="0.0" />
						</body>
					</body>
				</body>
			</body>
		</body>
		<camera name="camera_back" class="nmf" mode="fixed" ipd="0.068" pos="-8 0 1.0" euler="1.57 0.0 -1.57" />
		<camera name="camera_back_track" class="nmf" mode="track" ipd="0.068" pos="-12 0 6" euler="1.2 0.0 -1.57" />
		<camera name="camera_front" class="nmf" mode="fixed" ipd="0.068" pos="8 0 1.0" euler="1.57 0.0 1.57" />
		<camera name="camera_left" class="nmf" mode="fixed" ipd="0.068" pos="0 8 1.0" euler="-1.57 3.14 0" />
		<camera name="camera_right" class="nmf" mode="fixed" ipd="0.068" pos="0 -8 1.0" euler="1.57 0 0" />
		<camera name="camera_top_right" class="nmf" mode="fixed" ipd="0.068" pos="0 -8 5" euler="1.1 0 0" />
		<camera name="camera_top" class="nmf" mode="track" ipd="0.068" pos="0 0 8" euler="0 0 0" />
		<camera name="camera_top_zoomout" class="nmf" mode="track" ipd="0.068" pos="0 0 40" euler="0 0 0" />
		<camera name="camera_bottom" class="nmf" mode="track" ipd="0.068" pos="0 0 -8" euler="0 3.14 0" />
		<camera name="camera_right_front" class="nmf" mode="track" ipd="0.068" pos="4 -6 1.0" euler="1.57 0 0.588" />
		
		<camera name="camera_left_top_zoomout" class="nmf" mode="track" ipd="0.068" pos="0 8 5" euler="-2.129 3.14 0" />
		
		<camera name="camera_right_top_zoomout" class="nmf" mode="track" ipd="0.068" pos="0 -8 5" euler="1.011 0 0" />
		
		<camera name="camera_head_zoomin" class="nmf" mode="track" ipd="0.068" pos="3 -3 1" euler="1.57 0 0.72" fovy="30" />
		<camera name="camera_front_zoomin" class="nmf" mode="track" ipd="0.068" pos="8 0 1" euler="1.57 0 1.57" fovy="15" />
	</worldbody>
	<actuator>
		<position name="actuator_position_joint_Head_yaw" class="nmf" forcelimited="true" ctrlrange="-1000000 1000000" forcerange="-inf inf" joint="joint_Head_yaw" kp="0.9" />
		<velocity name="actuator_velocity_joint_Head_yaw" class="nmf" forcelimited="true" ctrlrange="-1000000 1000000" forcerange="-inf inf" joint="joint_Head_yaw" kv="0.0" />
		<motor name="actuator_torque_joint_Head_yaw" class="nmf" forcelimited="true" forcerange="-inf inf" joint="joint_Head_yaw" />
		<position name="actuator_position_joint_Head" class="nmf" forcelimited="true" ctrlrange="-1000000 1000000" forcerange="-inf inf" joint="joint_Head" kp="0.9" />
		<velocity name="actuator_velocity_joint_Head" class="nmf" forcelimited="true" ctrlrange="-1000000 1000000" forcerange="-inf inf" joint="joint_Head" kv="0.0" />
		<motor name="actuator_torque_joint_Head" class="nmf" forcelimited="true" forcerange="-inf inf" joint="joint_Head" />
		<position name="actuator_position_joint_Head_roll" class="nmf" forcelimited="true" ctrlrange="-1000000 1000000" forcerange="-inf inf" joint="joint_Head_roll" kp="0.01" />
		<velocity name="actuator_velocity_joint_Head_roll" class="nmf" forcelimited="true" ctrlrange="-1000000 1000000" forcerange="-inf inf" joint="joint_Head_roll" kv="0.0" />
		<motor name="actuator_torque_joint_Head_roll" class="nmf" forcelimited="true" forcerange="-inf inf" joint="joint_Head_roll" />
		<position name="actuator_position_joint_LPedicel_yaw" class="nmf" forcelimited="true" ctrlrange="-1000000 1000000" forcerange="-inf inf" joint="joint_LPedicel_yaw" kp="0.005" />
		<velocity name="actuator_velocity_joint_LPedicel_yaw" class="nmf" forcelimited="true" ctrlrange="-1000000 1000000" forcerange="-inf inf" joint="joint_LPedicel_yaw" kv="0.0" />
		<motor name="actuator_torque_joint_LPedicel_yaw" class="nmf" forcelimited="true" forcerange="-inf inf" joint="joint_LPedicel_yaw" />
		<position name="actuator_position_joint_LPedicel" class="nmf" forcelimited="true" ctrlrange="-1000000 1000000" forcerange="-inf inf" joint="joint_LPedicel" kp="0.4" />
		<velocity name="actuator_velocity_joint_LPedicel" class="nmf" forcelimited="true" ctrlrange="-1000000 1000000" forcerange="-inf inf" joint="joint_LPedicel" kv="0.0" />
		<motor name="actuator_torque_joint_LPedicel" class="nmf" forcelimited="true" forcerange="-inf inf" joint="joint_LPedicel" />
		<position name="actuator_position_joint_LPedicel_roll" class="nmf" forcelimited="true" ctrlrange="-1000000 1000000" forcerange="-inf inf" joint="joint_LPedicel_roll" kp="0.1" />
		<velocity name="actuator_velocity_joint_LPedicel_roll" class="nmf" forcelimited="true" ctrlrange="-1000000 1000000" forcerange="-inf inf" joint="joint_LPedicel_roll" kv="0.0" />
		<motor name="actuator_torque_joint_LPedicel_roll" class="nmf" forcelimited="true" forcerange="-inf inf" joint="joint_LPedicel_roll" />
		<position name="actuator_position_joint_LFuniculus" class="nmf" forcelimited="true" ctrlrange="-1000000 1000000" forcerange="-inf inf" joint="joint_LFuniculus" kp="1.0" />
		<velocity name="actuator_velocity_joint_LFuniculus" class="nmf" forcelimited="true" ctrlrange="-1000000 1000000" forcerange="-inf inf" joint="joint_LFuniculus" kv="0.0" />
		<motor name="actuator_torque_joint_LFuniculus" class="nmf" forcelimited="true" forcerange="-inf inf" joint="joint_LFuniculus" />
		<position name="actuator_position_joint_LFuniculus_roll" class="nmf" forcelimited="true" ctrlrange="-1000000 1000000" forcerange="-inf inf" joint="joint_LFuniculus_roll" kp="1.0" />
		<velocity name="actuator_velocity_joint_LFuniculus_roll" class="nmf" forcelimited="true" ctrlrange="-1000000 1000000" forcerange="-inf inf" joint="joint_LFuniculus_roll" kv="0.0" />
		<motor name="actuator_torque_joint_LFuniculus_roll" class="nmf" forcelimited="true" forcerange="-inf inf" joint="joint_LFuniculus_roll" />
		<position name="actuator_position_joint_LFuniculus_yaw" class="nmf" forcelimited="true" ctrlrange="-1000000 1000000" forcerange="-inf inf" joint="joint_LFuniculus_yaw" kp="1.0" />
		<velocity name="actuator_velocity_joint_LFuniculus_yaw" class="nmf" forcelimited="true" ctrlrange="-1000000 1000000" forcerange="-inf inf" joint="joint_LFuniculus_yaw" kv="0.0" />
		<motor name="actuator_torque_joint_LFuniculus_yaw" class="nmf" forcelimited="true" forcerange="-inf inf" joint="joint_LFuniculus_yaw" />
		<position name="actuator_position_joint_LArista" class="nmf" forcelimited="true" ctrlrange="-1000000 1000000" forcerange="-inf inf" joint="joint_LArista" kp="0.0001" />
		<velocity name="actuator_velocity_joint_LArista" class="nmf" forcelimited="true" ctrlrange="-1000000 1000000" forcerange="-inf inf" joint="joint_LArista" kv="0.0" />
		<motor name="actuator_torque_joint_LArista" class="nmf" forcelimited="true" forcerange="-inf inf" joint="joint_LArista" />
		<position name="actuator_position_joint_LArista_roll" class="nmf" forcelimited="true" ctrlrange="-1000000 1000000" forcerange="-inf inf" joint="joint_LArista_roll" kp="0.0001" />
		<velocity name="actuator_velocity_joint_LArista_roll" class="nmf" forcelimited="true" ctrlrange="-1000000 1000000" forcerange="-inf inf" joint="joint_LArista_roll" kv="0.0" />
		<motor name="actuator_torque_joint_LArista_roll" class="nmf" forcelimited="true" forcerange="-inf inf" joint="joint_LArista_roll" />
		<position name="actuator_position_joint_LArista_yaw" class="nmf" forcelimited="true" ctrlrange="-1000000 1000000" forcerange="-inf inf" joint="joint_LArista_yaw" kp="0.005" />
		<velocity name="actuator_velocity_joint_LArista_yaw" class="nmf" forcelimited="true" ctrlrange="-1000000 1000000" forcerange="-inf inf" joint="joint_LArista_yaw" kv="0.0" />
		<motor name="actuator_torque_joint_LArista_yaw" class="nmf" forcelimited="true" forcerange="-inf inf" joint="joint_LArista_yaw" />
		<position name="actuator_position_joint_RPedicel_yaw" class="nmf" forcelimited="true" ctrlrange="-1000000 1000000" forcerange="-inf inf" joint="joint_RPedicel_yaw" kp="0.005" />
		<velocity name="actuator_velocity_joint_RPedicel_yaw" class="nmf" forcelimited="true" ctrlrange="-1000000 1000000" forcerange="-inf inf" joint="joint_RPedicel_yaw" kv="0.0" />
		<motor name="actuator_torque_joint_RPedicel_yaw" class="nmf" forcelimited="true" forcerange="-inf inf" joint="joint_RPedicel_yaw" />
		<position name="actuator_position_joint_RPedicel" class="nmf" forcelimited="true" ctrlrange="-1000000 1000000" forcerange="-inf inf" joint="joint_RPedicel" kp="0.4" />
		<velocity name="actuator_velocity_joint_RPedicel" class="nmf" forcelimited="true" ctrlrange="-1000000 1000000" forcerange="-inf inf" joint="joint_RPedicel" kv="0.0" />
		<motor name="actuator_torque_joint_RPedicel" class="nmf" forcelimited="true" forcerange="-inf inf" joint="joint_RPedicel" />
		<position name="actuator_position_joint_RPedicel_roll" class="nmf" forcelimited="true" ctrlrange="-1000000 1000000" forcerange="-inf inf" joint="joint_RPedicel_roll" kp="0.1" />
		<velocity name="actuator_velocity_joint_RPedicel_roll" class="nmf" forcelimited="true" ctrlrange="-1000000 1000000" forcerange="-inf inf" joint="joint_RPedicel_roll" kv="0.0" />
		<motor name="actuator_torque_joint_RPedicel_roll" class="nmf" forcelimited="true" forcerange="-inf inf" joint="joint_RPedicel_roll" />
		<position name="actuator_position_joint_RFuniculus" class="nmf" forcelimited="true" ctrlrange="-1000000 1000000" forcerange="-inf inf" joint="joint_RFuniculus" kp="1.0" />
		<velocity name="actuator_velocity_joint_RFuniculus" class="nmf" forcelimited="true" ctrlrange="-1000000 1000000" forcerange="-inf inf" joint="joint_RFuniculus" kv="0.0" />
		<motor name="actuator_torque_joint_RFuniculus" class="nmf" forcelimited="true" forcerange="-inf inf" joint="joint_RFuniculus" />
		<position name="actuator_position_joint_RFuniculus_roll" class="nmf" forcelimited="true" ctrlrange="-1000000 1000000" forcerange="-inf inf" joint="joint_RFuniculus_roll" kp="1.0" />
		<velocity name="actuator_velocity_joint_RFuniculus_roll" class="nmf" forcelimited="true" ctrlrange="-1000000 1000000" forcerange="-inf inf" joint="joint_RFuniculus_roll" kv="0.0" />
		<motor name="actuator_torque_joint_RFuniculus_roll" class="nmf" forcelimited="true" forcerange="-inf inf" joint="joint_RFuniculus_roll" />
		<position name="actuator_position_joint_RFuniculus_yaw" class="nmf" forcelimited="true" ctrlrange="-1000000 1000000" forcerange="-inf inf" joint="joint_RFuniculus_yaw" kp="1.0" />
		<velocity name="actuator_velocity_joint_RFuniculus_yaw" class="nmf" forcelimited="true" ctrlrange="-1000000 1000000" forcerange="-inf inf" joint="joint_RFuniculus_yaw" kv="0.0" />
		<motor name="actuator_torque_joint_RFuniculus_yaw" class="nmf" forcelimited="true" forcerange="-inf inf" joint="joint_RFuniculus_yaw" />
		<position name="actuator_position_joint_RArista" class="nmf" forcelimited="true" ctrlrange="-1000000 1000000" forcerange="-inf inf" joint="joint_RArista" kp="0.005" />
		<velocity name="actuator_velocity_joint_RArista" class="nmf" forcelimited="true" ctrlrange="-1000000 1000000" forcerange="-inf inf" joint="joint_RArista" kv="0.0" />
		<motor name="actuator_torque_joint_RArista" class="nmf" forcelimited="true" forcerange="-inf inf" joint="joint_RArista" />
		<position name="actuator_position_joint_RArista_roll" class="nmf" forcelimited="true" ctrlrange="-1000000 1000000" forcerange="-inf inf" joint="joint_RArista_roll" kp="0.005" />
		<velocity name="actuator_velocity_joint_RArista_roll" class="nmf" forcelimited="true" ctrlrange="-1000000 1000000" forcerange="-inf inf" joint="joint_RArista_roll" kv="0.0" />
		<motor name="actuator_torque_joint_RArista_roll" class="nmf" forcelimited="true" forcerange="-inf inf" joint="joint_RArista_roll" />
		<position name="actuator_position_joint_RArista_yaw" class="nmf" forcelimited="true" ctrlrange="-1000000 1000000" forcerange="-inf inf" joint="joint_RArista_yaw" kp="0.005" />
		<velocity name="actuator_velocity_joint_RArista_yaw" class="nmf" forcelimited="true" ctrlrange="-1000000 1000000" forcerange="-inf inf" joint="joint_RArista_yaw" kv="0.0" />
		<motor name="actuator_torque_joint_RArista_yaw" class="nmf" forcelimited="true" forcerange="-inf inf" joint="joint_RArista_yaw" />
		<position name="actuator_position_joint_RFCoxa" class="nmf" forcelimited="true" ctrlrange="-1000000 1000000" forcerange="-inf inf" joint="joint_RFCoxa" kp="2.0" />
		<velocity name="actuator_velocity_joint_RFCoxa" class="nmf" forcelimited="true" ctrlrange="-1000000 1000000" forcerange="-inf inf" joint="joint_RFCoxa" kv="0.0" />
		<motor name="actuator_torque_joint_RFCoxa" class="nmf" forcelimited="true" forcerange="-inf inf" joint="joint_RFCoxa" />
		<position name="actuator_position_joint_RFCoxa_yaw" class="nmf" forcelimited="true" ctrlrange="-1000000 1000000" forcerange="-inf inf" joint="joint_RFCoxa_yaw" kp="2.0" />
		<velocity name="actuator_velocity_joint_RFCoxa_yaw" class="nmf" forcelimited="true" ctrlrange="-1000000 1000000" forcerange="-inf inf" joint="joint_RFCoxa_yaw" kv="0.0" />
		<motor name="actuator_torque_joint_RFCoxa_yaw" class="nmf" forcelimited="true" forcerange="-inf inf" joint="joint_RFCoxa_yaw" />
		<position name="actuator_position_joint_RFCoxa_roll" class="nmf" forcelimited="true" ctrlrange="-1000000 1000000" forcerange="-inf inf" joint="joint_RFCoxa_roll" kp="2.0" />
		<velocity name="actuator_velocity_joint_RFCoxa_roll" class="nmf" forcelimited="true" ctrlrange="-1000000 1000000" forcerange="-inf inf" joint="joint_RFCoxa_roll" kv="0.0" />
		<motor name="actuator_torque_joint_RFCoxa_roll" class="nmf" forcelimited="true" forcerange="-inf inf" joint="joint_RFCoxa_roll" />
		<position name="actuator_position_joint_RFFemur" class="nmf" forcelimited="true" ctrlrange="-1000000 1000000" forcerange="-inf inf" joint="joint_RFFemur" kp="2.0" />
		<velocity name="actuator_velocity_joint_RFFemur" class="nmf" forcelimited="true" ctrlrange="-1000000 1000000" forcerange="-inf inf" joint="joint_RFFemur" kv="0.0" />
		<motor name="actuator_torque_joint_RFFemur" class="nmf" forcelimited="true" forcerange="-inf inf" joint="joint_RFFemur" />
		<position name="actuator_position_joint_RFFemur_roll" class="nmf" forcelimited="true" ctrlrange="-1000000 1000000" forcerange="-inf inf" joint="joint_RFFemur_roll" kp="2.0" />
		<velocity name="actuator_velocity_joint_RFFemur_roll" class="nmf" forcelimited="true" ctrlrange="-1000000 1000000" forcerange="-inf inf" joint="joint_RFFemur_roll" kv="0.0" />
		<motor name="actuator_torque_joint_RFFemur_roll" class="nmf" forcelimited="true" forcerange="-inf inf" joint="joint_RFFemur_roll" />
		<position name="actuator_position_joint_RFTibia" class="nmf" forcelimited="true" ctrlrange="-1000000 1000000" forcerange="-inf inf" joint="joint_RFTibia" kp="2.0" />
		<velocity name="actuator_velocity_joint_RFTibia" class="nmf" forcelimited="true" ctrlrange="-1000000 1000000" forcerange="-inf inf" joint="joint_RFTibia" kv="0.0" />
		<motor name="actuator_torque_joint_RFTibia" class="nmf" forcelimited="true" forcerange="-inf inf" joint="joint_RFTibia" />
		<position name="actuator_position_joint_RFTarsus1" class="nmf" forcelimited="true" ctrlrange="-1000000 1000000" forcerange="-inf inf" joint="joint_RFTarsus1" kp="2.0" />
		<velocity name="actuator_velocity_joint_RFTarsus1" class="nmf" forcelimited="true" ctrlrange="-1000000 1000000" forcerange="-inf inf" joint="joint_RFTarsus1" kv="0.0" />
		<motor name="actuator_torque_joint_RFTarsus1" class="nmf" forcelimited="true" forcerange="-inf inf" joint="joint_RFTarsus1" />
		<position name="actuator_position_joint_LFCoxa" class="nmf" forcelimited="true" ctrlrange="-1000000 1000000" forcerange="-inf inf" joint="joint_LFCoxa" kp="2.0" />
		<velocity name="actuator_velocity_joint_LFCoxa" class="nmf" forcelimited="true" ctrlrange="-1000000 1000000" forcerange="-inf inf" joint="joint_LFCoxa" kv="0.0" />
		<motor name="actuator_torque_joint_LFCoxa" class="nmf" forcelimited="true" forcerange="-inf inf" joint="joint_LFCoxa" />
		<position name="actuator_position_joint_LFCoxa_yaw" class="nmf" forcelimited="true" ctrlrange="-1000000 1000000" forcerange="-inf inf" joint="joint_LFCoxa_yaw" kp="2.0" />
		<velocity name="actuator_velocity_joint_LFCoxa_yaw" class="nmf" forcelimited="true" ctrlrange="-1000000 1000000" forcerange="-inf inf" joint="joint_LFCoxa_yaw" kv="0.0" />
		<motor name="actuator_torque_joint_LFCoxa_yaw" class="nmf" forcelimited="true" forcerange="-inf inf" joint="joint_LFCoxa_yaw" />
		<position name="actuator_position_joint_LFCoxa_roll" class="nmf" forcelimited="true" ctrlrange="-1000000 1000000" forcerange="-inf inf" joint="joint_LFCoxa_roll" kp="2.0" />
		<velocity name="actuator_velocity_joint_LFCoxa_roll" class="nmf" forcelimited="true" ctrlrange="-1000000 1000000" forcerange="-inf inf" joint="joint_LFCoxa_roll" kv="0.0" />
		<motor name="actuator_torque_joint_LFCoxa_roll" class="nmf" forcelimited="true" forcerange="-inf inf" joint="joint_LFCoxa_roll" />
		<position name="actuator_position_joint_LFFemur" class="nmf" forcelimited="true" ctrlrange="-1000000 1000000" forcerange="-inf inf" joint="joint_LFFemur" kp="2.0" />
		<velocity name="actuator_velocity_joint_LFFemur" class="nmf" forcelimited="true" ctrlrange="-1000000 1000000" forcerange="-inf inf" joint="joint_LFFemur" kv="0.0" />
		<motor name="actuator_torque_joint_LFFemur" class="nmf" forcelimited="true" forcerange="-inf inf" joint="joint_LFFemur" />
		<position name="actuator_position_joint_LFFemur_roll" class="nmf" forcelimited="true" ctrlrange="-1000000 1000000" forcerange="-inf inf" joint="joint_LFFemur_roll" kp="2.0" />
		<velocity name="actuator_velocity_joint_LFFemur_roll" class="nmf" forcelimited="true" ctrlrange="-1000000 1000000" forcerange="-inf inf" joint="joint_LFFemur_roll" kv="0.0" />
		<motor name="actuator_torque_joint_LFFemur_roll" class="nmf" forcelimited="true" forcerange="-inf inf" joint="joint_LFFemur_roll" />
		<position name="actuator_position_joint_LFTibia" class="nmf" forcelimited="true" ctrlrange="-1000000 1000000" forcerange="-inf inf" joint="joint_LFTibia" kp="2.0" />
		<velocity name="actuator_velocity_joint_LFTibia" class="nmf" forcelimited="true" ctrlrange="-1000000 1000000" forcerange="-inf inf" joint="joint_LFTibia" kv="0.0" />
		<motor name="actuator_torque_joint_LFTibia" class="nmf" forcelimited="true" forcerange="-inf inf" joint="joint_LFTibia" />
		<position name="actuator_position_joint_LFTarsus1" class="nmf" forcelimited="true" ctrlrange="-1000000 1000000" forcerange="-inf inf" joint="joint_LFTarsus1" kp="2.0" />
		<velocity name="actuator_velocity_joint_LFTarsus1" class="nmf" forcelimited="true" ctrlrange="-1000000 1000000" forcerange="-inf inf" joint="joint_LFTarsus1" kv="0.0" />
		<motor name="actuator_torque_joint_LFTarsus1" class="nmf" forcelimited="true" forcerange="-inf inf" joint="joint_LFTarsus1" />
		<position name="actuator_position_joint_RMCoxa" class="nmf" forcelimited="true" ctrlrange="-1000000 1000000" forcerange="-inf inf" joint="joint_RMCoxa" kp="2.0" />
		<velocity name="actuator_velocity_joint_RMCoxa" class="nmf" forcelimited="true" ctrlrange="-1000000 1000000" forcerange="-inf inf" joint="joint_RMCoxa" kv="0.0" />
		<motor name="actuator_torque_joint_RMCoxa" class="nmf" forcelimited="true" forcerange="-inf inf" joint="joint_RMCoxa" />
		<position name="actuator_position_joint_RMCoxa_yaw" class="nmf" forcelimited="true" ctrlrange="-1000000 1000000" forcerange="-inf inf" joint="joint_RMCoxa_yaw" kp="2.0" />
		<velocity name="actuator_velocity_joint_RMCoxa_yaw" class="nmf" forcelimited="true" ctrlrange="-1000000 1000000" forcerange="-inf inf" joint="joint_RMCoxa_yaw" kv="0.0" />
		<motor name="actuator_torque_joint_RMCoxa_yaw" class="nmf" forcelimited="true" forcerange="-inf inf" joint="joint_RMCoxa_yaw" />
		<position name="actuator_position_joint_RMCoxa_roll" class="nmf" forcelimited="true" ctrlrange="-1000000 1000000" forcerange="-inf inf" joint="joint_RMCoxa_roll" kp="2.0" />
		<velocity name="actuator_velocity_joint_RMCoxa_roll" class="nmf" forcelimited="true" ctrlrange="-1000000 1000000" forcerange="-inf inf" joint="joint_RMCoxa_roll" kv="0.0" />
		<motor name="actuator_torque_joint_RMCoxa_roll" class="nmf" forcelimited="true" forcerange="-inf inf" joint="joint_RMCoxa_roll" />
		<position name="actuator_position_joint_RMFemur" class="nmf" forcelimited="true" ctrlrange="-1000000 1000000" forcerange="-inf inf" joint="joint_RMFemur" kp="2.0" />
		<velocity name="actuator_velocity_joint_RMFemur" class="nmf" forcelimited="true" ctrlrange="-1000000 1000000" forcerange="-inf inf" joint="joint_RMFemur" kv="0.0" />
		<motor name="actuator_torque_joint_RMFemur" class="nmf" forcelimited="true" forcerange="-inf inf" joint="joint_RMFemur" />
		<position name="actuator_position_joint_RMFemur_roll" class="nmf" forcelimited="true" ctrlrange="-1000000 1000000" forcerange="-inf inf" joint="joint_RMFemur_roll" kp="2.0" />
		<velocity name="actuator_velocity_joint_RMFemur_roll" class="nmf" forcelimited="true" ctrlrange="-1000000 1000000" forcerange="-inf inf" joint="joint_RMFemur_roll" kv="0.0" />
		<motor name="actuator_torque_joint_RMFemur_roll" class="nmf" forcelimited="true" forcerange="-inf inf" joint="joint_RMFemur_roll" />
		<position name="actuator_position_joint_RMTibia" class="nmf" forcelimited="true" ctrlrange="-1000000 1000000" forcerange="-inf inf" joint="joint_RMTibia" kp="2.0" />
		<velocity name="actuator_velocity_joint_RMTibia" class="nmf" forcelimited="true" ctrlrange="-1000000 1000000" forcerange="-inf inf" joint="joint_RMTibia" kv="0.0" />
		<motor name="actuator_torque_joint_RMTibia" class="nmf" forcelimited="true" forcerange="-inf inf" joint="joint_RMTibia" />
		<position name="actuator_position_joint_RMTarsus1" class="nmf" forcelimited="true" ctrlrange="-1000000 1000000" forcerange="-inf inf" joint="joint_RMTarsus1" kp="2.0" />
		<velocity name="actuator_velocity_joint_RMTarsus1" class="nmf" forcelimited="true" ctrlrange="-1000000 1000000" forcerange="-inf inf" joint="joint_RMTarsus1" kv="0.0" />
		<motor name="actuator_torque_joint_RMTarsus1" class="nmf" forcelimited="true" forcerange="-inf inf" joint="joint_RMTarsus1" />
		<position name="actuator_position_joint_LMCoxa" class="nmf" forcelimited="true" ctrlrange="-1000000 1000000" forcerange="-inf inf" joint="joint_LMCoxa" kp="2.0" />
		<velocity name="actuator_velocity_joint_LMCoxa" class="nmf" forcelimited="true" ctrlrange="-1000000 1000000" forcerange="-inf inf" joint="joint_LMCoxa" kv="0.0" />
		<motor name="actuator_torque_joint_LMCoxa" class="nmf" forcelimited="true" forcerange="-inf inf" joint="joint_LMCoxa" />
		<position name="actuator_position_joint_LMCoxa_yaw" class="nmf" forcelimited="true" ctrlrange="-1000000 1000000" forcerange="-inf inf" joint="joint_LMCoxa_yaw" kp="2.0" />
		<velocity name="actuator_velocity_joint_LMCoxa_yaw" class="nmf" forcelimited="true" ctrlrange="-1000000 1000000" forcerange="-inf inf" joint="joint_LMCoxa_yaw" kv="0.0" />
		<motor name="actuator_torque_joint_LMCoxa_yaw" class="nmf" forcelimited="true" forcerange="-inf inf" joint="joint_LMCoxa_yaw" />
		<position name="actuator_position_joint_LMCoxa_roll" class="nmf" forcelimited="true" ctrlrange="-1000000 1000000" forcerange="-inf inf" joint="joint_LMCoxa_roll" kp="2.0" />
		<velocity name="actuator_velocity_joint_LMCoxa_roll" class="nmf" forcelimited="true" ctrlrange="-1000000 1000000" forcerange="-inf inf" joint="joint_LMCoxa_roll" kv="0.0" />
		<motor name="actuator_torque_joint_LMCoxa_roll" class="nmf" forcelimited="true" forcerange="-inf inf" joint="joint_LMCoxa_roll" />
		<position name="actuator_position_joint_LMFemur" class="nmf" forcelimited="true" ctrlrange="-1000000 1000000" forcerange="-inf inf" joint="joint_LMFemur" kp="2.0" />
		<velocity name="actuator_velocity_joint_LMFemur" class="nmf" forcelimited="true" ctrlrange="-1000000 1000000" forcerange="-inf inf" joint="joint_LMFemur" kv="0.0" />
		<motor name="actuator_torque_joint_LMFemur" class="nmf" forcelimited="true" forcerange="-inf inf" joint="joint_LMFemur" />
		<position name="actuator_position_joint_LMFemur_roll" class="nmf" forcelimited="true" ctrlrange="-1000000 1000000" forcerange="-inf inf" joint="joint_LMFemur_roll" kp="2.0" />
		<velocity name="actuator_velocity_joint_LMFemur_roll" class="nmf" forcelimited="true" ctrlrange="-1000000 1000000" forcerange="-inf inf" joint="joint_LMFemur_roll" kv="0.0" />
		<motor name="actuator_torque_joint_LMFemur_roll" class="nmf" forcelimited="true" forcerange="-inf inf" joint="joint_LMFemur_roll" />
		<position name="actuator_position_joint_LMTibia" class="nmf" forcelimited="true" ctrlrange="-1000000 1000000" forcerange="-inf inf" joint="joint_LMTibia" kp="2.0" />
		<velocity name="actuator_velocity_joint_LMTibia" class="nmf" forcelimited="true" ctrlrange="-1000000 1000000" forcerange="-inf inf" joint="joint_LMTibia" kv="0.0" />
		<motor name="actuator_torque_joint_LMTibia" class="nmf" forcelimited="true" forcerange="-inf inf" joint="joint_LMTibia" />
		<position name="actuator_position_joint_LMTarsus1" class="nmf" forcelimited="true" ctrlrange="-1000000 1000000" forcerange="-inf inf" joint="joint_LMTarsus1" kp="2.0" />
		<velocity name="actuator_velocity_joint_LMTarsus1" class="nmf" forcelimited="true" ctrlrange="-1000000 1000000" forcerange="-inf inf" joint="joint_LMTarsus1" kv="0.0" />
		<motor name="actuator_torque_joint_LMTarsus1" class="nmf" forcelimited="true" forcerange="-inf inf" joint="joint_LMTarsus1" />
		<position name="actuator_position_joint_RHCoxa" class="nmf" forcelimited="true" ctrlrange="-1000000 1000000" forcerange="-inf inf" joint="joint_RHCoxa" kp="2.0" />
		<velocity name="actuator_velocity_joint_RHCoxa" class="nmf" forcelimited="true" ctrlrange="-1000000 1000000" forcerange="-inf inf" joint="joint_RHCoxa" kv="0.0" />
		<motor name="actuator_torque_joint_RHCoxa" class="nmf" forcelimited="true" forcerange="-inf inf" joint="joint_RHCoxa" />
		<position name="actuator_position_joint_RHCoxa_yaw" class="nmf" forcelimited="true" ctrlrange="-1000000 1000000" forcerange="-inf inf" joint="joint_RHCoxa_yaw" kp="2.0" />
		<velocity name="actuator_velocity_joint_RHCoxa_yaw" class="nmf" forcelimited="true" ctrlrange="-1000000 1000000" forcerange="-inf inf" joint="joint_RHCoxa_yaw" kv="0.0" />
		<motor name="actuator_torque_joint_RHCoxa_yaw" class="nmf" forcelimited="true" forcerange="-inf inf" joint="joint_RHCoxa_yaw" />
		<position name="actuator_position_joint_RHCoxa_roll" class="nmf" forcelimited="true" ctrlrange="-1000000 1000000" forcerange="-inf inf" joint="joint_RHCoxa_roll" kp="2.0" />
		<velocity name="actuator_velocity_joint_RHCoxa_roll" class="nmf" forcelimited="true" ctrlrange="-1000000 1000000" forcerange="-inf inf" joint="joint_RHCoxa_roll" kv="0.0" />
		<motor name="actuator_torque_joint_RHCoxa_roll" class="nmf" forcelimited="true" forcerange="-inf inf" joint="joint_RHCoxa_roll" />
		<position name="actuator_position_joint_RHFemur" class="nmf" forcelimited="true" ctrlrange="-1000000 1000000" forcerange="-inf inf" joint="joint_RHFemur" kp="2.0" />
		<velocity name="actuator_velocity_joint_RHFemur" class="nmf" forcelimited="true" ctrlrange="-1000000 1000000" forcerange="-inf inf" joint="joint_RHFemur" kv="0.0" />
		<motor name="actuator_torque_joint_RHFemur" class="nmf" forcelimited="true" forcerange="-inf inf" joint="joint_RHFemur" />
		<position name="actuator_position_joint_RHFemur_roll" class="nmf" forcelimited="true" ctrlrange="-1000000 1000000" forcerange="-inf inf" joint="joint_RHFemur_roll" kp="2.0" />
		<velocity name="actuator_velocity_joint_RHFemur_roll" class="nmf" forcelimited="true" ctrlrange="-1000000 1000000" forcerange="-inf inf" joint="joint_RHFemur_roll" kv="0.0" />
		<motor name="actuator_torque_joint_RHFemur_roll" class="nmf" forcelimited="true" forcerange="-inf inf" joint="joint_RHFemur_roll" />
		<position name="actuator_position_joint_RHTibia" class="nmf" forcelimited="true" ctrlrange="-1000000 1000000" forcerange="-inf inf" joint="joint_RHTibia" kp="2.0" />
		<velocity name="actuator_velocity_joint_RHTibia" class="nmf" forcelimited="true" ctrlrange="-1000000 1000000" forcerange="-inf inf" joint="joint_RHTibia" kv="0.0" />
		<motor name="actuator_torque_joint_RHTibia" class="nmf" forcelimited="true" forcerange="-inf inf" joint="joint_RHTibia" />
		<position name="actuator_position_joint_RHTarsus1" class="nmf" forcelimited="true" ctrlrange="-1000000 1000000" forcerange="-inf inf" joint="joint_RHTarsus1" kp="2.0" />
		<velocity name="actuator_velocity_joint_RHTarsus1" class="nmf" forcelimited="true" ctrlrange="-1000000 1000000" forcerange="-inf inf" joint="joint_RHTarsus1" kv="0.0" />
		<motor name="actuator_torque_joint_RHTarsus1" class="nmf" forcelimited="true" forcerange="-inf inf" joint="joint_RHTarsus1" />
		<position name="actuator_position_joint_LHCoxa" class="nmf" forcelimited="true" ctrlrange="-1000000 1000000" forcerange="-inf inf" joint="joint_LHCoxa" kp="2.0" />
		<velocity name="actuator_velocity_joint_LHCoxa" class="nmf" forcelimited="true" ctrlrange="-1000000 1000000" forcerange="-inf inf" joint="joint_LHCoxa" kv="0.0" />
		<motor name="actuator_torque_joint_LHCoxa" class="nmf" forcelimited="true" forcerange="-inf inf" joint="joint_LHCoxa" />
		<position name="actuator_position_joint_LHCoxa_yaw" class="nmf" forcelimited="true" ctrlrange="-1000000 1000000" forcerange="-inf inf" joint="joint_LHCoxa_yaw" kp="2.0" />
		<velocity name="actuator_velocity_joint_LHCoxa_yaw" class="nmf" forcelimited="true" ctrlrange="-1000000 1000000" forcerange="-inf inf" joint="joint_LHCoxa_yaw" kv="0.0" />
		<motor name="actuator_torque_joint_LHCoxa_yaw" class="nmf" forcelimited="true" forcerange="-inf inf" joint="joint_LHCoxa_yaw" />
		<position name="actuator_position_joint_LHCoxa_roll" class="nmf" forcelimited="true" ctrlrange="-1000000 1000000" forcerange="-inf inf" joint="joint_LHCoxa_roll" kp="2.0" />
		<velocity name="actuator_velocity_joint_LHCoxa_roll" class="nmf" forcelimited="true" ctrlrange="-1000000 1000000" forcerange="-inf inf" joint="joint_LHCoxa_roll" kv="0.0" />
		<motor name="actuator_torque_joint_LHCoxa_roll" class="nmf" forcelimited="true" forcerange="-inf inf" joint="joint_LHCoxa_roll" />
		<position name="actuator_position_joint_LHFemur" class="nmf" forcelimited="true" ctrlrange="-1000000 1000000" forcerange="-inf inf" joint="joint_LHFemur" kp="2.0" />
		<velocity name="actuator_velocity_joint_LHFemur" class="nmf" forcelimited="true" ctrlrange="-1000000 1000000" forcerange="-inf inf" joint="joint_LHFemur" kv="0.0" />
		<motor name="actuator_torque_joint_LHFemur" class="nmf" forcelimited="true" forcerange="-inf inf" joint="joint_LHFemur" />
		<position name="actuator_position_joint_LHFemur_roll" class="nmf" forcelimited="true" ctrlrange="-1000000 1000000" forcerange="-inf inf" joint="joint_LHFemur_roll" kp="2.0" />
		<velocity name="actuator_velocity_joint_LHFemur_roll" class="nmf" forcelimited="true" ctrlrange="-1000000 1000000" forcerange="-inf inf" joint="joint_LHFemur_roll" kv="0.0" />
		<motor name="actuator_torque_joint_LHFemur_roll" class="nmf" forcelimited="true" forcerange="-inf inf" joint="joint_LHFemur_roll" />
		<position name="actuator_position_joint_LHTibia" class="nmf" forcelimited="true" ctrlrange="-1000000 1000000" forcerange="-inf inf" joint="joint_LHTibia" kp="2.0" />
		<velocity name="actuator_velocity_joint_LHTibia" class="nmf" forcelimited="true" ctrlrange="-1000000 1000000" forcerange="-inf inf" joint="joint_LHTibia" kv="0.0" />
		<motor name="actuator_torque_joint_LHTibia" class="nmf" forcelimited="true" forcerange="-inf inf" joint="joint_LHTibia" />
		<position name="actuator_position_joint_LHTarsus1" class="nmf" forcelimited="true" ctrlrange="-1000000 1000000" forcerange="-inf inf" joint="joint_LHTarsus1" kp="2.0" />
		<velocity name="actuator_velocity_joint_LHTarsus1" class="nmf" forcelimited="true" ctrlrange="-1000000 1000000" forcerange="-inf inf" joint="joint_LHTarsus1" kv="0.0" />
		<motor name="actuator_torque_joint_LHTarsus1" class="nmf" forcelimited="true" forcerange="-inf inf" joint="joint_LHTarsus1" />
	</actuator>
	<sensor>
  </sensor>
</mujoco>